Workbook

Sheet 09 12+21+22 (TOTAL)
J1: Forma FD-048BL Aprobat prin ordinul Ministrului al Finanțelor al Republicii Moldova nr. _______ al _________
A2: ORG2 | B2: F1F3 | C2: P1P2 | D2: P3
A3: TOTAL | B3: 09 | C3: 88 | D3: TOTAL
A4: REȚEA, STATE ȘI CONTINGENTE ALE INSTITUȚIILOR
A5: ÎN PERIOADA 12 LUNI. 2025
A6: Denumirea indicatorului | E6: CF | F6: CR | G6: Aprobat la începutul anului | H6: Aprobat la sfârșitul anului | I6: Numărul mediu prevazut pe an | J6: Numărul mediu realizat la mm.dd.20__ | K6: Real încadrat la începutul anului | L6: Real încadrat la sfârsitul perioadei
A8: RAPORT nr. 3-8 privind învățămîntul primar, gimnazial și liceal | F8: 8
A9: Instituții în total, inclusiv | E9: 1 | F9: 46030 | G9: ='0912 (TOTAL)'!G9+'0921 (TOTAL)'!G9+'0922 (TOTAL)'!G9 -> 21 | H9: ='0912 (TOTAL)'!H9+'0921 (TOTAL)'!H9+'0922 (TOTAL)'!H9 -> 21 | I9: x | J9: x | K9: =H9 -> 21 | L9: ='0912 (TOTAL)'!L9+'0921 (TOTAL)'!L9+'0922 (TOTAL)'!L9 -> 21
A10: filiale | E10: 10 | F10: 46061 | G10: ='0912 (TOTAL)'!G10+'0921 (TOTAL)'!G10+'0922 (TOTAL)'!G10 -> 0 | H10: ='0912 (TOTAL)'!H10+'0921 (TOTAL)'!H10+'0922 (TOTAL)'!H10 -> 0 | I10: x | J10: x | K10: =G10 -> 0 | L10: ='0912 (TOTAL)'!L10+'0921 (TOTAL)'!L10+'0922 (TOTAL)'!L10 -> 0
A11: Unități în state (posturi) în total, inclusiv | E11: 101 | F11: 46089 | G11: =G12+G16+G19 -> 278.4 | H11: =H12+H16+H19 -> 324.63 | I11: =I12+I16+I19 -> 322.63 | J11: =J12+J16+J19 -> 0 | K11: =K12+K16+K19 -> 278.4 | L11: =L12+L16+L19 -> 0
A12: funcții didactice, inclusiv | E12: 102 | F12: 46120 | G12: =SUM(G13:G14) -> 187.65 | H12: =SUM(H13:H14) -> 204.43 | I12: =SUM(I13:I14) -> 204.43 | J12: =SUM(J13:J14) -> 0 | K12: =SUM(K13:K14) -> 187.65 | L12: =SUM(L13:L14) -> 0
A13: de conducere | E13: 126 | F13: 46150 | G13: ='0912 (TOTAL)'!G13+'0921 (TOTAL)'!G13+'0922 (TOTAL)'!G13 -> 17.25 | H13: ='0912 (TOTAL)'!H13+'0921 (TOTAL)'!H13+'0922 (TOTAL)'!H13 -> 20.5 | I13: ='0912 (TOTAL)'!I13+'0921 (TOTAL)'!I13+'0922 (TOTAL)'!I13 -> 20.5 | J13: ='0912 (TOTAL)'!J13+'0921 (TOTAL)'!J13+'0922 (TOTAL)'!J13 -> 0 | K13: =G13 -> 17.25 | L13: ='0912 (TOTAL)'!L13+'0921 (TOTAL)'!L13+'0922 (TOTAL)'!L13 -> 0
A14: de execuție din care | E14: 145 | F14: 46181 | G14: ='0912 (TOTAL)'!G14+'0921 (TOTAL)'!G14+'0922 (TOTAL)'!G14 -> 170.4 | H14: ='0912 (TOTAL)'!H14+'0921 (TOTAL)'!H14+'0922 (TOTAL)'!H14 -> 183.93 | I14: ='0912 (TOTAL)'!I14+'0921 (TOTAL)'!I14+'0922 (TOTAL)'!I14 -> 183.93 | J14: ='0912 (TOTAL)'!J14+'0921 (TOTAL)'!J14+'0922 (TOTAL)'!J14 -> 0 | K14: =G14 -> 170.4 | L14: ='0912 (TOTAL)'!L14+'0921 (TOTAL)'!L14+'0922 (TOTAL)'!L14 -> 0
A15: cadre didactice de sprijin | E15: 146 | F15: 46211 | G15: ='0912 (TOTAL)'!G15+'0921 (TOTAL)'!G15+'0922 (TOTAL)'!G15 -> 20.09 | H15: ='0912 (TOTAL)'!H15+'0921 (TOTAL)'!H15+'0922 (TOTAL)'!H15 -> 27.2 | I15: ='0912 (TOTAL)'!I15+'0921 (TOTAL)'!I15+'0922 (TOTAL)'!I15 -> 27.2 | J15: ='0912 (TOTAL)'!J15+'0921 (TOTAL)'!J15+'0922 (TOTAL)'!J15 -> 0 | K15: =G15 -> 20.09 | L15: ='0912 (TOTAL)'!L15+'0921 (TOTAL)'!L15+'0922 (TOTAL)'!L15 -> 0
A16: funcții de specialitate, inclusiv | E16: 103 | F16: 46242 | G16: =SUM(G17:G18) -> 19.5 | H16: =SUM(H17:H18) -> 24.25 | I16: =SUM(I17:I18) -> 24.25 | J16: =SUM(J17:J18) -> 0 | K16: =SUM(K17:K18) -> 19.5 | L16: =SUM(L17:L18) -> 0
A17: de conducere | E17: 126 | F17: 46273 | G17: ='0912 (TOTAL)'!G17+'0921 (TOTAL)'!G17+'0922 (TOTAL)'!G17 -> 3 | H17: ='0912 (TOTAL)'!H17+'0921 (TOTAL)'!H17+'0922 (TOTAL)'!H17 -> 2.5 | I17: ='0912 (TOTAL)'!I17+'0921 (TOTAL)'!I17+'0922 (TOTAL)'!I17 -> 2.5 | J17: ='0912 (TOTAL)'!J17+'0921 (TOTAL)'!J17+'0922 (TOTAL)'!J17 -> 0 | K17: =G17 -> 3 | L17: ='0912 (TOTAL)'!L17+'0921 (TOTAL)'!L17+'0922 (TOTAL)'!L17 -> 0
A18: de execuție | E18: 145 | F18: 46303 | G18: ='0912 (TOTAL)'!G18+'0921 (TOTAL)'!G18+'0922 (TOTAL)'!G18 -> 16.5 | H18: ='0912 (TOTAL)'!H18+'0921 (TOTAL)'!H18+'0922 (TOTAL)'!H18 -> 21.75 | I18: ='0912 (TOTAL)'!I18+'0921 (TOTAL)'!I18+'0922 (TOTAL)'!I18 -> 21.75 | J18: ='0912 (TOTAL)'!J18+'0921 (TOTAL)'!J18+'0922 (TOTAL)'!J18 -> 0 | K18: =G18 -> 16.5 | L18: ='0912 (TOTAL)'!L18+'0921 (TOTAL)'!L18+'0922 (TOTAL)'!L18 -> 0
A19: funcții complexe, inclusiv | E19: 104 | F19: 46334 | G19: =SUM(G20:G22) -> 71.25 | H19: =SUM(H20:H22) -> 95.95 | I19: =SUM(I20:I22) -> 93.95 | J19: =SUM(J20:J22) -> 0 | K19: =SUM(K20:K22) -> 71.25 | L19: =SUM(L20:L22) -> 0
A20: de conducere | E20: 126 | F20: 46364 | G20: ='0912 (TOTAL)'!G20+'0921 (TOTAL)'!G20+'0922 (TOTAL)'!G20 -> 0 | H20: ='0912 (TOTAL)'!H20+'0921 (TOTAL)'!H20+'0922 (TOTAL)'!H20 -> 0 | I20: ='0912 (TOTAL)'!I20+'0921 (TOTAL)'!I20+'0922 (TOTAL)'!I20 -> 0 | J20: ='0912 (TOTAL)'!J20+'0921 (TOTAL)'!J20+'0922 (TOTAL)'!J20 -> 0 | K20: =G20 -> 0 | L20: ='0912 (TOTAL)'!L20+'0921 (TOTAL)'!L20+'0922 (TOTAL)'!L20 -> 0
A21: de execuție | E21: 145 | F21: 8.13 | G21: ='0912 (TOTAL)'!G21+'0921 (TOTAL)'!G21+'0922 (TOTAL)'!G21 -> 1 | H21: ='0912 (TOTAL)'!H21+'0921 (TOTAL)'!H21+'0922 (TOTAL)'!H21 -> 3 | I21: ='0912 (TOTAL)'!I21+'0921 (TOTAL)'!I21+'0922 (TOTAL)'!I21 -> 3 | J21: ='0912 (TOTAL)'!J21+'0921 (TOTAL)'!J21+'0922 (TOTAL)'!J21 -> 0 | K21: =G21 -> 1 | L21: ='0912 (TOTAL)'!L21+'0921 (TOTAL)'!L21+'0922 (TOTAL)'!L21 -> 0
A22: muncitori | E22: 177 | F22: 8.14 | G22: ='0912 (TOTAL)'!G22+'0921 (TOTAL)'!G22+'0922 (TOTAL)'!G22 -> 70.25 | H22: ='0912 (TOTAL)'!H22+'0921 (TOTAL)'!H22+'0922 (TOTAL)'!H22 -> 92.95 | I22: ='0912 (TOTAL)'!I22+'0921 (TOTAL)'!I22+'0922 (TOTAL)'!I22 -> 90.95 | J22: ='0912 (TOTAL)'!J22+'0921 (TOTAL)'!J22+'0922 (TOTAL)'!J22 -> 0 | K22: =G22 -> 70.25 | L22: ='0912 (TOTAL)'!L22+'0921 (TOTAL)'!L22+'0922 (TOTAL)'!L22 -> 0
A23: Personal angajat în total, inclusiv | E23: 100 | F23: 8.15 | G23: =G24+G28+G31 -> 280 | H23: =H24+H28+H31 -> 284 | I23: x | J23: =J24+J28+J31 -> 0 | K23: =K24+K28+K31 -> 280 | L23: =L24+L28+L31 -> 0
A24: funcții didactice, inclusiv | E24: 105 | F24: 8.16 | G24: =SUM(G25:G26) -> 185 | H24: =SUM(H25:H26) -> 190 | I24: x | J24: =SUM(J25:J26) -> 0 | K24: =SUM(K25:K26) -> 185 | L24: =SUM(L25:L26) -> 0
A25: de conducere | E25: 120 | F25: 8.17 | G25: ='0912 (TOTAL)'!G25+'0921 (TOTAL)'!G25+'0922 (TOTAL)'!G25 -> 22 | H25: ='0912 (TOTAL)'!H25+'0921 (TOTAL)'!H25+'0922 (TOTAL)'!H25 -> 22 | I25: x | J25: ='0912 (TOTAL)'!J25+'0921 (TOTAL)'!J25+'0922 (TOTAL)'!J25 -> 0 | K25: =G25 -> 22 | L25: ='0912 (TOTAL)'!L25+'0921 (TOTAL)'!L25+'0922 (TOTAL)'!L25 -> 0
A26: de execuție, din care | E26: 140 | F26: 8.18 | G26: ='0912 (TOTAL)'!G26+'0921 (TOTAL)'!G26+'0922 (TOTAL)'!G26 -> 163 | H26: ='0912 (TOTAL)'!H26+'0921 (TOTAL)'!H26+'0922 (TOTAL)'!H26 -> 168 | I26: x | J26: ='0912 (TOTAL)'!J26+'0921 (TOTAL)'!J26+'0922 (TOTAL)'!J26 -> 0 | K26: =G26 -> 163 | L26: ='0912 (TOTAL)'!L26+'0921 (TOTAL)'!L26+'0922 (TOTAL)'!L26 -> 0
A27: cadre didactice de sprijin | E27: 147 | F27: 8.19 | G27: ='0912 (TOTAL)'!G27+'0921 (TOTAL)'!G27+'0922 (TOTAL)'!G27 -> 19 | H27: ='0912 (TOTAL)'!H27+'0921 (TOTAL)'!H27+'0922 (TOTAL)'!H27 -> 21 | I27: x | J27: ='0912 (TOTAL)'!J27+'0921 (TOTAL)'!J27+'0922 (TOTAL)'!J27 -> 0 | K27: =G27 -> 19 | L27: ='0912 (TOTAL)'!L27+'0921 (TOTAL)'!L27+'0922 (TOTAL)'!L27 -> 0
A28: funcții de specialitate, inclusiv | E28: 106 | F28: 8.20 | G28: =SUM(G29:G30) -> 21 | H28: =SUM(H29:H30) -> 20 | I28: x | J28: =SUM(J29:J30) -> 0 | K28: =SUM(K29:K30) -> 21 | L28: =SUM(L29:L30) -> 0
A29: de conducere | E29: 120 | F29: 8.21 | G29: ='0912 (TOTAL)'!G29+'0921 (TOTAL)'!G29+'0922 (TOTAL)'!G29 -> 3 | H29: ='0912 (TOTAL)'!H29+'0921 (TOTAL)'!H29+'0922 (TOTAL)'!H29 -> 3 | I29: x | J29: ='0912 (TOTAL)'!J29+'0921 (TOTAL)'!J29+'0922 (TOTAL)'!J29 -> 0 | K29: =G29 -> 3 | L29: ='0912 (TOTAL)'!L29+'0921 (TOTAL)'!L29+'0922 (TOTAL)'!L29 -> 0
A30: de execuție | E30: 140 | F30: 8.22 | G30: ='0912 (TOTAL)'!G30+'0921 (TOTAL)'!G30+'0922 (TOTAL)'!G30 -> 18 | H30: ='0912 (TOTAL)'!H30+'0921 (TOTAL)'!H30+'0922 (TOTAL)'!H30 -> 17 | I30: x | J30: ='0912 (TOTAL)'!J30+'0921 (TOTAL)'!J30+'0922 (TOTAL)'!J30 -> 0 | K30: =G30 -> 18 | L30: ='0912 (TOTAL)'!L30+'0921 (TOTAL)'!L30+'0922 (TOTAL)'!L30 -> 0
A31: funcții complexe, inclusiv | E31: 107 | F31: 8.23 | G31: =SUM(G32:G34) -> 74 | H31: =SUM(H32:H34) -> 74 | I31: x | J31: =SUM(J32:J34) -> 0 | K31: =SUM(K32:K34) -> 74 | L31: =SUM(L32:L34) -> 0
A32: de conducere | E32: 120 | F32: 8.24 | G32: ='0912 (TOTAL)'!G32+'0921 (TOTAL)'!G32+'0922 (TOTAL)'!G32 -> 0 | H32: ='0912 (TOTAL)'!H32+'0921 (TOTAL)'!H32+'0922 (TOTAL)'!H32 -> 0 | I32: x | J32: ='0912 (TOTAL)'!J32+'0921 (TOTAL)'!J32+'0922 (TOTAL)'!J32 -> 0 | K32: =G32 -> 0 | L32: ='0912 (TOTAL)'!L32+'0921 (TOTAL)'!L32+'0922 (TOTAL)'!L32 -> 0
A33: de execuție | E33: 140 | F33: 8.25 | G33: ='0912 (TOTAL)'!G33+'0921 (TOTAL)'!G33+'0922 (TOTAL)'!G33 -> 0 | H33: ='0912 (TOTAL)'!H33+'0921 (TOTAL)'!H33+'0922 (TOTAL)'!H33 -> 1 | I33: x | J33: ='0912 (TOTAL)'!J33+'0921 (TOTAL)'!J33+'0922 (TOTAL)'!J33 -> 0 | K33: =G33 -> 0 | L33: ='0912 (TOTAL)'!L33+'0921 (TOTAL)'!L33+'0922 (TOTAL)'!L33 -> 0
A34: muncitori | E34: 175 | F34: 8.26 | G34: ='0912 (TOTAL)'!G34+'0921 (TOTAL)'!G34+'0922 (TOTAL)'!G34 -> 74 | H34: ='0912 (TOTAL)'!H34+'0921 (TOTAL)'!H34+'0922 (TOTAL)'!H34 -> 73 | I34: x | J34: ='0912 (TOTAL)'!J34+'0921 (TOTAL)'!J34+'0922 (TOTAL)'!J34 -> 0 | K34: =G34 -> 74 | L34: ='0912 (TOTAL)'!L34+'0921 (TOTAL)'!L34+'0922 (TOTAL)'!L34 -> 0
A35: Numărul personalului didactic beneficiar de compensații anuale, inclusiv | E35: 108 | F35: 8.27 | G35: =SUM(G36:G37) -> 256 | H35: =SUM(H36:H37) -> 272 | I35: x | J35: x | K35: =SUM(K36:K37) -> 256 | L35: =SUM(L36:L37) -> 118
A36: cu funcție de conducere | E36: 120 | F36: 8.28 | G36: ='0912 (TOTAL)'!G36+'0921 (TOTAL)'!G36+'0922 (TOTAL)'!G36 -> 32 | H36: ='0912 (TOTAL)'!H36+'0921 (TOTAL)'!H36+'0922 (TOTAL)'!H36 -> 32 | I36: x | J36: x | K36: =G36 -> 32 | L36: ='0912 (TOTAL)'!L36+'0921 (TOTAL)'!L36+'0922 (TOTAL)'!L36 -> 15
A37: cu funcție de execuție | E37: 140 | F37: 8.29 | G37: ='0912 (TOTAL)'!G37+'0921 (TOTAL)'!G37+'0922 (TOTAL)'!G37 -> 224 | H37: ='0912 (TOTAL)'!H37+'0921 (TOTAL)'!H37+'0922 (TOTAL)'!H37 -> 240 | I37: x | J37: x | K37: =G37 -> 224 | L37: ='0912 (TOTAL)'!L37+'0921 (TOTAL)'!L37+'0922 (TOTAL)'!L37 -> 103
A38: Retibuirea muncii în total, inclusiv | E38: 500 | F38: 8.30 | G38: x | H38: x | I38: =I39+I43+I46 -> 31027500 | J38: =J39+J43+J46 -> 0 | K38: x | L38: x
A39: funcții didactice, inclusiv | E39: 501 | F39: 8.31 | G39: x | H39: x | I39: =SUM(I40:I41) -> 23769300 | J39: =SUM(J40:J41) -> 0 | K39: x | L39: x
A40: de conducere | E40: 510 | F40: 8.32 | G40: x | H40: x | I40: ='0912 (TOTAL)'!I40+'0921 (TOTAL)'!I40+'0922 (TOTAL)'!I40 -> 3550000 | J40: ='0912 (TOTAL)'!J40+'0921 (TOTAL)'!J40+'0922 (TOTAL)'!J40 -> 0 | K40: x | L40: x
A41: de execuție, din care | E41: 540 | F41: 8.33 | G41: x | H41: x | I41: ='0912 (TOTAL)'!I41+'0921 (TOTAL)'!I41+'0922 (TOTAL)'!I41 -> 20219300 | J41: ='0912 (TOTAL)'!J41+'0921 (TOTAL)'!J41+'0922 (TOTAL)'!J41 -> 0 | K41: x | L41: x
...

Sheet 09 12+21+22 (00203)
A1: Învățământ primar, gimnazial, liceal (Activitatea de bază) | J1: Forma FD-048BL Aprobat prin ordinul Ministrului al Finanțelor al Republicii Moldova nr. _______ al _________
A2: ORG2 | B2: F1F3 | C2: P1P2 | D2: P3
A3: TOTAL | B3: 09 | C3: 88 | D3: 00200
A4: REȚEA, STATE ȘI CONTINGENTE ALE INSTITUȚIILOR
A5: ÎN PERIOADA 12 LUNI. 2025
A6: Denumirea indicatorului | E6: CF | F6: CR | G6: Aprobat la începutul anului | H6: Aprobat la sfârșitul anului | I6: Numărul mediu prevazut pe an | J6: Numărul mediu realizat la mm.dd.20__ | K6: Real încadrat la începutul anului | L6: Real încadrat la sfârsitul perioadei
A8: RAPORT nr. 3-8 privind învățămîntul primar, gimnazial și liceal | F8: 8
A9: Instituții în total, inclusiv | E9: 1 | F9: 46030 | I9: x | J9: x | K9: ='09 12+21+22 (TOTAL)'!K9 -> 21
A10: filiale | E10: 10 | F10: 46061 | G10: ='09 12+21+22 (TOTAL)'!G10 -> 0 | H10: ='09 12+21+22 (TOTAL)'!H10 -> 0 | I10: x | J10: x | K10: ='09 12+21+22 (TOTAL)'!K10 -> 0 | L10: ='09 12+21+22 (TOTAL)'!L10 -> 0
A11: Unități în state (posturi) în total, inclusiv | E11: 101 | F11: 46089 | G11: =G12+G16+G19 -> 108 | H11: =H12+H16+H19 -> 324.63 | I11: =I12+I16+I19 -> 322.63 | J11: =J12+J16+J19 -> 0 | K11: =K12+K16+K19 -> 278.4 | L11: =L12+L16+L19 -> 0
A12: funcții didactice, inclusiv | E12: 102 | F12: 46120 | G12: =SUM(G13) -> 17.25 | H12: =SUM(H13:H14) -> 204.43 | I12: =SUM(I13:I14) -> 204.43 | J12: =SUM(J13:J14) -> 0 | K12: =SUM(K13:K14) -> 187.65 | L12: =SUM(L13:L14) -> 0
A13: de conducere | E13: 126 | F13: 46150 | G13: ='09 12+21+22 (TOTAL)'!G13 -> 17.25 | H13: ='09 12+21+22 (TOTAL)'!H13 -> 20.5 | I13: ='09 12+21+22 (TOTAL)'!I13 -> 20.5 | J13: ='09 12+21+22 (TOTAL)'!J13 -> 0 | K13: ='09 12+21+22 (TOTAL)'!K13 -> 17.25 | L13: ='09 12+21+22 (TOTAL)'!L13 -> 0
A14: de execuție din care | E14: 145 | F14: 46181 | G14: ='09 12+21+22 (TOTAL)'!G14 -> 170.4 | H14: ='09 12+21+22 (TOTAL)'!H14 -> 183.93 | I14: ='09 12+21+22 (TOTAL)'!I14 -> 183.93 | J14: ='09 12+21+22 (TOTAL)'!J14 -> 0 | K14: ='09 12+21+22 (TOTAL)'!K14 -> 170.4 | L14: ='09 12+21+22 (TOTAL)'!L14 -> 0
A15: cadre didactice de sprijin | E15: 146 | F15: 46211 | G15: ='09 12+21+22 (TOTAL)'!G15 -> 20.09 | H15: ='09 12+21+22 (TOTAL)'!H15 -> 27.2 | I15: ='09 12+21+22 (TOTAL)'!I15 -> 27.2 | J15: ='09 12+21+22 (TOTAL)'!J15 -> 0 | K15: ='09 12+21+22 (TOTAL)'!K15 -> 20.09 | L15: ='09 12+21+22 (TOTAL)'!L15 -> 0
A16: funcții de specialitate, inclusiv | E16: 103 | F16: 46242 | G16: =SUM(G17:G18) -> 19.5 | H16: =SUM(H17:H18) -> 24.25 | I16: =SUM(I17:I18) -> 24.25 | J16: =SUM(J17:J18) -> 0 | K16: =SUM(K17:K18) -> 19.5 | L16: =SUM(L17:L18) -> 0
A17: de conducere | E17: 126 | F17: 46273 | G17: ='09 12+21+22 (TOTAL)'!G17 -> 3 | H17: ='09 12+21+22 (TOTAL)'!H17 -> 2.5 | I17: ='09 12+21+22 (TOTAL)'!I17 -> 2.5 | J17: ='09 12+21+22 (TOTAL)'!J17 -> 0 | K17: ='09 12+21+22 (TOTAL)'!K17 -> 3 | L17: ='09 12+21+22 (TOTAL)'!L17 -> 0
A18: de execuție | E18: 145 | F18: 46303 | G18: ='09 12+21+22 (TOTAL)'!G18 -> 16.5 | H18: ='09 12+21+22 (TOTAL)'!H18 -> 21.75 | I18: ='09 12+21+22 (TOTAL)'!I18 -> 21.75 | J18: ='09 12+21+22 (TOTAL)'!J18 -> 0 | K18: ='09 12+21+22 (TOTAL)'!K18 -> 16.5 | L18: ='09 12+21+22 (TOTAL)'!L18 -> 0
A19: funcții complexe, inclusiv | E19: 104 | F19: 46334 | G19: =SUM(G20:G22) -> 71.25 | H19: =SUM(H20:H22) -> 95.95 | I19: =SUM(I20:I22) -> 93.95 | J19: =SUM(J20:J22) -> 0 | K19: =SUM(K20:K22) -> 71.25 | L19: =SUM(L20:L22) -> 0
A20: de conducere | E20: 126 | F20: 46364 | G20: ='09 12+21+22 (TOTAL)'!G20 -> 0 | H20: ='09 12+21+22 (TOTAL)'!H20 -> 0 | I20: ='09 12+21+22 (TOTAL)'!I20 -> 0 | J20: ='09 12+21+22 (TOTAL)'!J20 -> 0 | K20: ='09 12+21+22 (TOTAL)'!K20 -> 0 | L20: ='09 12+21+22 (TOTAL)'!L20 -> 0
A21: de execuție | E21: 145 | F21: 8.13 | G21: ='09 12+21+22 (TOTAL)'!G21 -> 1 | H21: ='09 12+21+22 (TOTAL)'!H21 -> 3 | I21: ='09 12+21+22 (TOTAL)'!I21 -> 3 | J21: ='09 12+21+22 (TOTAL)'!J21 -> 0 | K21: ='09 12+21+22 (TOTAL)'!K21 -> 1 | L21: ='09 12+21+22 (TOTAL)'!L21 -> 0
A22: muncitori | E22: 177 | F22: 8.14 | G22: ='09 12+21+22 (TOTAL)'!G22 -> 70.25 | H22: ='09 12+21+22 (TOTAL)'!H22 -> 92.95 | I22: ='09 12+21+22 (TOTAL)'!I22 -> 90.95 | J22: ='09 12+21+22 (TOTAL)'!J22 -> 0 | K22: ='09 12+21+22 (TOTAL)'!K22 -> 70.25 | L22: ='09 12+21+22 (TOTAL)'!L22 -> 0
A23: Personal angajat în total, inclusiv | E23: 100 | F23: 8.15 | G23: =G24+G28+G31 -> 280 | H23: =H24+H28+H31 -> 284 | I23: x | J23: =J24+J28+J31 -> 0 | K23: =K24+K28+K31 -> 280 | L23: =L24+L28+L31 -> 0
A24: funcții didactice, inclusiv | E24: 105 | F24: 8.16 | G24: =SUM(G25:G26) -> 185 | H24: =SUM(H25:H26) -> 190 | I24: x | J24: =SUM(J25:J26) -> 0 | K24: =SUM(K25:K26) -> 185 | L24: =SUM(L25:L26) -> 0
A25: de conducere | E25: 120 | F25: 8.17 | G25: ='09 12+21+22 (TOTAL)'!G25 -> 22 | H25: ='09 12+21+22 (TOTAL)'!H25 -> 22 | I25: x | J25: ='09 12+21+22 (TOTAL)'!J25 -> 0 | K25: ='09 12+21+22 (TOTAL)'!K25 -> 22 | L25: ='09 12+21+22 (TOTAL)'!L25 -> 0
A26: de execuție, din care | E26: 140 | F26: 8.18 | G26: ='09 12+21+22 (TOTAL)'!G26 -> 163 | H26: ='09 12+21+22 (TOTAL)'!H26 -> 168 | I26: x | J26: ='09 12+21+22 (TOTAL)'!J26 -> 0 | K26: ='09 12+21+22 (TOTAL)'!K26 -> 163 | L26: ='09 12+21+22 (TOTAL)'!L26 -> 0
A27: cadre didactice de sprijin | E27: 147 | F27: 8.19 | G27: ='09 12+21+22 (TOTAL)'!G27 -> 19 | H27: ='09 12+21+22 (TOTAL)'!H27 -> 21 | I27: x | J27: ='09 12+21+22 (TOTAL)'!J27 -> 0 | K27: ='09 12+21+22 (TOTAL)'!K27 -> 19 | L27: ='09 12+21+22 (TOTAL)'!L27 -> 0
A28: funcții de specialitate, inclusiv | E28: 106 | F28: 8.20 | G28: =SUM(G29:G30) -> 21 | H28: =SUM(H29:H30) -> 20 | I28: x | J28: =SUM(J29:J30) -> 0 | K28: =SUM(K29:K30) -> 21 | L28: =SUM(L29:L30) -> 0
A29: de conducere | E29: 120 | F29: 8.21 | G29: ='09 12+21+22 (TOTAL)'!G29 -> 3 | H29: ='09 12+21+22 (TOTAL)'!H29 -> 3 | I29: x | J29: ='09 12+21+22 (TOTAL)'!J29 -> 0 | K29: ='09 12+21+22 (TOTAL)'!K29 -> 3 | L29: ='09 12+21+22 (TOTAL)'!L29 -> 0
A30: de execuție | E30: 140 | F30: 8.22 | G30: ='09 12+21+22 (TOTAL)'!G30 -> 18 | H30: ='09 12+21+22 (TOTAL)'!H30 -> 17 | I30: x | J30: ='09 12+21+22 (TOTAL)'!J30 -> 0 | K30: ='09 12+21+22 (TOTAL)'!K30 -> 18 | L30: ='09 12+21+22 (TOTAL)'!L30 -> 0
A31: funcții complexe, inclusiv | E31: 107 | F31: 8.23 | G31: =SUM(G32:G34) -> 74 | H31: =SUM(H32:H34) -> 74 | I31: x | J31: =SUM(J32:J34) -> 0 | K31: =SUM(K32:K34) -> 74 | L31: =SUM(L32:L34) -> 0
A32: de conducere | E32: 120 | F32: 8.24 | G32: ='09 12+21+22 (TOTAL)'!G32 -> 0 | H32: ='09 12+21+22 (TOTAL)'!H32 -> 0 | I32: x | J32: ='09 12+21+22 (TOTAL)'!J32 -> 0 | K32: ='09 12+21+22 (TOTAL)'!K32 -> 0 | L32: ='09 12+21+22 (TOTAL)'!L32 -> 0
A33: de execuție | E33: 140 | F33: 8.25 | G33: ='09 12+21+22 (TOTAL)'!G33 -> 0 | H33: ='09 12+21+22 (TOTAL)'!H33 -> 1 | I33: x | J33: ='09 12+21+22 (TOTAL)'!J33 -> 0 | K33: ='09 12+21+22 (TOTAL)'!K33 -> 0 | L33: ='09 12+21+22 (TOTAL)'!L33 -> 0
A34: muncitori | E34: 175 | F34: 8.26 | G34: ='09 12+21+22 (TOTAL)'!G34 -> 74 | H34: ='09 12+21+22 (TOTAL)'!H34 -> 73 | I34: x | J34: ='09 12+21+22 (TOTAL)'!J34 -> 0 | K34: ='09 12+21+22 (TOTAL)'!K34 -> 74 | L34: ='09 12+21+22 (TOTAL)'!L34 -> 0
A35: Numărul personalului didactic beneficiar de compensații anuale, inclusiv | E35: 108 | F35: 8.27 | G35: =SUM(G36:G37) -> 0 | H35: =SUM(H36:H37) -> 0 | I35: x | J35: x | K35: =SUM(K36:K37) -> 0 | L35: =SUM(L36:L37) -> 0
A36: cu funcție de conducere | E36: 120 | F36: 8.28 | I36: x | J36: x
A37: cu funcție de execuție | E37: 140 | F37: 8.29 | I37: x | J37: x
A38: Retibuirea muncii în total, inclusiv | E38: 500 | F38: 8.30 | G38: x | H38: x | I38: =I39+I43+I46 -> 31027500 | J38: =J39+J43+J46 -> 0 | K38: x | L38: x
A39: funcții didactice, inclusiv | E39: 501 | F39: 8.31 | G39: x | H39: x | I39: =SUM(I40:I41) -> 23769300 | J39: =SUM(J40:J41) -> 0 | K39: x | L39: x
A40: de conducere | E40: 510 | F40: 8.32 | G40: x | H40: x | I40: ='09 12+21+22 (TOTAL)'!I40 -> 3550000 | J40: ='09 12+21+22 (TOTAL)'!J40 -> 0 | K40: x | L40: x
A41: de execuție, din care | E41: 540 | F41: 8.33 | G41: x | H41: x | I41: ='09 12+21+22 (TOTAL)'!I41 -> 20219300 | J41: ='09 12+21+22 (TOTAL)'!J41 -> 0 | K41: x | L41: x
...

Sheet 09 12+21+22 (0044482)
A1: Învățământ primar, gimnazial, liceal (Alimentația) | J1: Forma FD-048BL Aprobat prin ordinul Ministrului al Finanțelor al Republicii Moldova nr. _______ al _________
A2: ORG2 | B2: F1F3 | C2: P1P2 | D2: P3
A3: TOTAL | B3: 09 | C3: 88 | D3: 00448
A4: REȚEA, STATE ȘI CONTINGENTE ALE INSTITUȚIILOR
A5: ÎN PERIOADA 12 LUNI. 2025
A6: Denumirea indicatorului | E6: CF | F6: CR | G6: Aprobat la începutul anului | H6: Aprobat la sfârșitul anului | I6: Numărul mediu prevazut pe an | J6: Numărul mediu realizat la mm.dd.20__ | K6: Real încadrat la începutul anului | L6: Real încadrat la sfârsitul perioadei
A8: RAPORT nr. 3-8 privind învățămîntul primar, gimnazial și liceal | F8: 8
A9: Instituții în total, inclusiv | E9: 1 | F9: 46030 | I9: x | J9: x
A10: filiale | E10: 10 | F10: 46061 | I10: x | J10: x
A11: Unități în state (posturi) în total, inclusiv | E11: 101 | F11: 46089 | G11: =G12+G16+G19 -> 0 | H11: =H12+H16+H19 -> 0 | I11: =I12+I16+I19 -> 0 | J11: =J12+J16+J19 -> 0 | K11: =K12+K16+K19 -> 0 | L11: =L12+L16+L19 -> 0
A12: funcții didactice, inclusiv | E12: 102 | F12: 46120 | G12: =SUM(G13:G14) -> 0 | H12: =SUM(H13:H14) -> 0 | I12: =SUM(I13:I14) -> 0 | J12: =SUM(J13:J14) -> 0 | K12: =SUM(K13:K14) -> 0 | L12: =SUM(L13:L14) -> 0
A13: de conducere | E13: 126 | F13: 46150
A14: de execuție din care | E14: 145 | F14: 46181
A15: cadre didactice de sprijin | E15: 146 | F15: 46211
A16: funcții de specialitate, inclusiv | E16: 103 | F16: 46242 | G16: =SUM(G17:G18) -> 0 | H16: =SUM(H17:H18) -> 0 | I16: =SUM(I17:I18) -> 0 | J16: =SUM(J17:J18) -> 0 | K16: =SUM(K17:K18) -> 0 | L16: =SUM(L17:L18) -> 0
A17: de conducere | E17: 126 | F17: 46273
A18: de execuție | E18: 145 | F18: 46303
A19: funcții complexe, inclusiv | E19: 104 | F19: 46334 | G19: =SUM(G20:G22) -> 0 | H19: =SUM(H20:H22) -> 0 | I19: =SUM(I20:I22) -> 0 | J19: =SUM(J20:J22) -> 0 | K19: =SUM(K20:K22) -> 0 | L19: =SUM(L20:L22) -> 0
A20: de conducere | E20: 126 | F20: 46364
A21: de execuție | E21: 145 | F21: 8.13
A22: muncitori | E22: 177 | F22: 8.14
A23: Personal angajat în total, inclusiv | E23: 100 | F23: 8.15 | G23: =G24+G28+G31 -> 0 | H23: =H24+H28+H31 -> 0 | I23: x | J23: =J24+J28+J31 -> 0 | K23: =K24+K28+K31 -> 0 | L23: =L24+L28+L31 -> 0
A24: funcții didactice, inclusiv | E24: 105 | F24: 8.16 | G24: =SUM(G25:G26) -> 0 | H24: =SUM(H25:H26) -> 0 | I24: x | J24: =SUM(J25:J26) -> 0 | K24: =SUM(K25:K26) -> 0 | L24: =SUM(L25:L26) -> 0
A25: de conducere | E25: 120 | F25: 8.17 | I25: x
A26: de execuție, din care | E26: 140 | F26: 8.18 | I26: x
A27: cadre didactice de sprijin | E27: 147 | F27: 8.19 | I27: x
A28: funcții de specialitate, inclusiv | E28: 106 | F28: 8.20 | G28: =SUM(G29:G30) -> 0 | H28: =SUM(H29:H30) -> 0 | I28: x | J28: =SUM(J29:J30) -> 0 | K28: =SUM(K29:K30) -> 0 | L28: =SUM(L29:L30) -> 0
A29: de conducere | E29: 120 | F29: 8.21 | I29: x
A30: de execuție | E30: 140 | F30: 8.22 | I30: x
A31: funcții complexe, inclusiv | E31: 107 | F31: 8.23 | G31: =SUM(G32:G34) -> 0 | H31: =SUM(H32:H34) -> 0 | I31: x | J31: =SUM(J32:J34) -> 0 | K31: =SUM(K32:K34) -> 0 | L31: =SUM(L32:L34) -> 0
A32: de conducere | E32: 120 | F32: 8.24 | I32: x
A33: de execuție | E33: 140 | F33: 8.25 | I33: x
A34: muncitori | E34: 175 | F34: 8.26 | I34: x
A35: Numărul personalului didactic beneficiar de compensații anuale, inclusiv | E35: 108 | F35: 8.27 | G35: =SUM(G36:G37) -> 0 | H35: =SUM(H36:H37) -> 0 | I35: x | J35: x | K35: =SUM(K36:K37) -> 0 | L35: =SUM(L36:L37) -> 0
A36: cu funcție de conducere | E36: 120 | F36: 8.28 | I36: x | J36: x
A37: cu funcție de execuție | E37: 140 | F37: 8.29 | I37: x | J37: x
A38: Retibuirea muncii în total, inclusiv | E38: 500 | F38: 8.30 | G38: x | H38: x | I38: =I39+I43+I46 -> 0 | J38: =J39+J43+J46 -> 0 | K38: x | L38: x
A39: funcții didactice, inclusiv | E39: 501 | F39: 8.31 | G39: x | H39: x | I39: =SUM(I40:I41) -> 0 | J39: =SUM(J40:J41) -> 0 | K39: x | L39: x
A40: de conducere | E40: 510 | F40: 8.32 | G40: x | H40: x | K40: x | L40: x
A41: de execuție, din care | E41: 540 | F41: 8.33 | G41: x | H41: x | K41: x | L41: x
...

Sheet 09 12+21+22 (00492)
A1: Învățământ primar, gimnazial, liceal (Compensații) | J1: Forma FD-048BL Aprobat prin ordinul Ministrului al Finanțelor al Republicii Moldova nr. _______ al _________
A2: ORG2 | B2: F1F3 | C2: P1P2 | D2: P3
A3: TOTAL | B3: 09 | C3: 88 | D3: 00492
A4: REȚEA, STATE ȘI CONTINGENTE ALE INSTITUȚIILOR
A5: ÎN PERIOADA 12 LUNI. 2025
A6: Denumirea indicatorului | E6: CF | F6: CR | G6: Aprobat la începutul anului | H6: Aprobat la sfârșitul anului | I6: Numărul mediu prevazut pe an | J6: Numărul mediu realizat la mm.dd.20__ | K6: Real încadrat la începutul anului | L6: Real încadrat la sfârsitul perioadei
A8: RAPORT nr. 3-8 privind învățămîntul primar, gimnazial și liceal | F8: 8
A9: Instituții în total, inclusiv | E9: 1 | F9: 46030 | I9: x | J9: x
A10: filiale | E10: 10 | F10: 46061 | I10: x | J10: x
A11: Unități în state (posturi) în total, inclusiv | E11: 101 | F11: 46089 | G11: =G12+G16+G19 -> 0 | H11: =H12+H16+H19 -> 0 | I11: =I12+I16+I19 -> 0 | J11: =J12+J16+J19 -> 0 | K11: =K12+K16+K19 -> 0 | L11: =L12+L16+L19 -> 0
A12: funcții didactice, inclusiv | E12: 102 | F12: 46120 | G12: =SUM(G13:G14) -> 0 | H12: =SUM(H13:H14) -> 0 | I12: =SUM(I13:I14) -> 0 | J12: =SUM(J13:J14) -> 0 | K12: =SUM(K13:K14) -> 0 | L12: =SUM(L13:L14) -> 0
A13: de conducere | E13: 126 | F13: 46150
A14: de execuție din care | E14: 145 | F14: 46181
A15: cadre didactice de sprijin | E15: 146 | F15: 46211
A16: funcții de specialitate, inclusiv | E16: 103 | F16: 46242 | G16: =SUM(G17:G18) -> 0 | H16: =SUM(H17:H18) -> 0 | I16: =SUM(I17:I18) -> 0 | J16: =SUM(J17:J18) -> 0 | K16: =SUM(K17:K18) -> 0 | L16: =SUM(L17:L18) -> 0
A17: de conducere | E17: 126 | F17: 46273
A18: de execuție | E18: 145 | F18: 46303
A19: funcții complexe, inclusiv | E19: 104 | F19: 46334 | G19: =SUM(G20:G22) -> 0 | H19: =SUM(H20:H22) -> 0 | I19: =SUM(I20:I22) -> 0 | J19: =SUM(J20:J22) -> 0 | K19: =SUM(K20:K22) -> 0 | L19: =SUM(L20:L22) -> 0
A20: de conducere | E20: 126 | F20: 46364
A21: de execuție | E21: 145 | F21: 8.13
A22: muncitori | E22: 177 | F22: 8.14
A23: Personal angajat în total, inclusiv | E23: 100 | F23: 8.15 | G23: =G24+G28+G31 -> 0 | H23: =H24+H28+H31 -> 0 | I23: x | J23: =J24+J28+J31 -> 0 | K23: =K24+K28+K31 -> 0 | L23: =L24+L28+L31 -> 0
A24: funcții didactice, inclusiv | E24: 105 | F24: 8.16 | G24: =SUM(G25:G26) -> 0 | H24: =SUM(H25:H26) -> 0 | I24: x | J24: =SUM(J25:J26) -> 0 | K24: =SUM(K25:K26) -> 0 | L24: =SUM(L25:L26) -> 0
A25: de conducere | E25: 120 | F25: 8.17 | I25: x
A26: de execuție, din care | E26: 140 | F26: 8.18 | I26: x
A27: cadre didactice de sprijin | E27: 147 | F27: 8.19 | I27: x
A28: funcții de specialitate, inclusiv | E28: 106 | F28: 8.20 | G28: =SUM(G29:G30) -> 0 | H28: =SUM(H29:H30) -> 0 | I28: x | J28: =SUM(J29:J30) -> 0 | K28: =SUM(K29:K30) -> 0 | L28: =SUM(L29:L30) -> 0
A29: de conducere | E29: 120 | F29: 8.21 | I29: x
A30: de execuție | E30: 140 | F30: 8.22 | I30: x
A31: funcții complexe, inclusiv | E31: 107 | F31: 8.23 | G31: =SUM(G32:G34) -> 0 | H31: =SUM(H32:H34) -> 0 | I31: x | J31: =SUM(J32:J34) -> 0 | K31: =SUM(K32:K34) -> 0 | L31: =SUM(L32:L34) -> 0
A32: de conducere | E32: 120 | F32: 8.24 | I32: x
A33: de execuție | E33: 140 | F33: 8.25 | I33: x
A34: muncitori | E34: 175 | F34: 8.26 | I34: x
A35: Numărul personalului didactic beneficiar de compensații anuale, inclusiv | E35: 108 | F35: 8.27 | G35: =SUM(G36:G37) -> 256 | H35: =SUM(H36:H37) -> 272 | I35: x | J35: x | K35: =SUM(K36:K37) -> 256 | L35: =SUM(L36:L37) -> 118
A36: cu funcție de conducere | E36: 120 | F36: 8.28 | G36: ='09 12+21+22 (TOTAL)'!G36 -> 32 | H36: ='09 12+21+22 (TOTAL)'!H36 -> 32 | I36: x | J36: x | K36: ='09 12+21+22 (TOTAL)'!K36 -> 32 | L36: ='09 12+21+22 (TOTAL)'!L36 -> 15
A37: cu funcție de execuție | E37: 140 | F37: 8.29 | G37: ='09 12+21+22 (TOTAL)'!G37 -> 224 | H37: ='09 12+21+22 (TOTAL)'!H37 -> 240 | I37: x | J37: x | K37: ='09 12+21+22 (TOTAL)'!K37 -> 224 | L37: ='09 12+21+22 (TOTAL)'!L37 -> 103
A38: Retibuirea muncii în total, inclusiv | E38: 500 | F38: 8.30 | G38: x | H38: x | I38: =I39+I43+I46 -> 0 | J38: =J39+J43+J46 -> 0 | K38: x | L38: x
A39: funcții didactice, inclusiv | E39: 501 | F39: 8.31 | G39: x | H39: x | I39: =SUM(I40:I41) -> 0 | J39: =SUM(J40:J41) -> 0 | K39: x | L39: x
A40: de conducere | E40: 510 | F40: 8.32 | G40: x | H40: x | K40: x | L40: x
A41: de execuție, din care | E41: 540 | F41: 8.33 | G41: x | H41: x | K41: x | L41: x
...

Sheet 0912 (TOTAL)
A1: Învățământ primar | J1: Forma FD-048BL Aprobat prin ordinul Ministrului al Finanțelor al Republicii Moldova nr. _______ al _________
A2: ORG2 | B2: F1F3 | C2: P1P2 | D2: P3
A3: TOTAL | B3: 0912 | C3: 8803 | D3: TOTAL
A4: REȚEA, STATE ȘI CONTINGENTE ALE INSTITUȚIILOR
A5: ÎN PERIOADA 12 LUNI. 2025
A6: Denumirea indicatorului | E6: CF | F6: CR | G6: Aprobat la începutul anului | H6: Aprobat la sfârșitul anului | I6: Numărul mediu prevazut pe an | J6: Numărul mediu realizat la mm.dd.20__ | K6: Real încadrat la începutul anului | L6: Real încadrat la sfârsitul perioadei
A8: RAPORT nr. 3-8 privind învățămîntul primar, gimnazial și liceal | F8: 8
A9: Instituții în total, inclusiv | E9: 1 | F9: 46030 | G9: ='09881 (TOTAL)'!G9+'14279 (TOTAL)'!G9 -> 2 | H9: ='09881 (TOTAL)'!H9+'14279 (TOTAL)'!H9 -> 2 | I9: x | J9: x | K9: =H9 -> 2 | L9: ='09881 (TOTAL)'!L9+'14279 (TOTAL)'!L9 -> 2
A10: filiale | E10: 10 | F10: 46061 | G10: ='09881 (TOTAL)'!G10+'14279 (TOTAL)'!G10 -> 0 | H10: ='09881 (TOTAL)'!H10+'14279 (TOTAL)'!H10 -> 0 | I10: x | J10: x | K10: =G10 -> 0 | L10: ='09881 (TOTAL)'!L10+'14279 (TOTAL)'!L10 -> 0
A11: Unități în state (posturi) în total, inclusiv | E11: 101 | F11: 46089 | G11: =G12+G16+G19 -> 0 | H11: =H12+H16+H19 -> 0 | I11: =I12+I16+I19 -> 0 | J11: =J12+J16+J19 -> 0 | K11: =K12+K16+K19 -> 0 | L11: =L12+L16+L19 -> 0
A12: funcții didactice, inclusiv | E12: 102 | F12: 46120 | G12: =SUM(G13:G14) -> 0 | H12: =SUM(H13:H14) -> 0 | I12: =SUM(I13:I14) -> 0 | J12: =SUM(J13:J14) -> 0 | K12: =SUM(K13:K14) -> 0 | L12: =SUM(L13:L14) -> 0
A13: de conducere | E13: 126 | F13: 46150 | G13: ='09881 (TOTAL)'!G13+'14279 (TOTAL)'!G13 -> 0 | H13: ='09881 (TOTAL)'!H13+'14279 (TOTAL)'!H13 -> 0 | I13: ='09881 (TOTAL)'!I13+'14279 (TOTAL)'!I13 -> 0 | J13: ='09881 (TOTAL)'!J13+'14279 (TOTAL)'!J13 -> 0 | K13: =G13 -> 0 | L13: ='09881 (TOTAL)'!L13+'14279 (TOTAL)'!L13 -> 0
A14: de execuție din care | E14: 145 | F14: 46181 | G14: ='09881 (TOTAL)'!G14+'14279 (TOTAL)'!G14 -> 0 | H14: ='09881 (TOTAL)'!H14+'14279 (TOTAL)'!H14 -> 0 | I14: ='09881 (TOTAL)'!I14+'14279 (TOTAL)'!I14 -> 0 | J14: ='09881 (TOTAL)'!J14+'14279 (TOTAL)'!J14 -> 0 | K14: =G14 -> 0 | L14: ='09881 (TOTAL)'!L14+'14279 (TOTAL)'!L14 -> 0
A15: cadre didactice de sprijin | E15: 146 | F15: 46211 | G15: ='09881 (TOTAL)'!G15+'14279 (TOTAL)'!G15 -> 0 | H15: ='09881 (TOTAL)'!H15+'14279 (TOTAL)'!H15 -> 0 | I15: ='09881 (TOTAL)'!I15+'14279 (TOTAL)'!I15 -> 0 | J15: ='09881 (TOTAL)'!J15+'14279 (TOTAL)'!J15 -> 0 | K15: =G15 -> 0 | L15: ='09881 (TOTAL)'!L15+'14279 (TOTAL)'!L15 -> 0
A16: funcții de specialitate, inclusiv | E16: 103 | F16: 46242 | G16: =SUM(G17:G18) -> 0 | H16: =SUM(H17:H18) -> 0 | I16: =SUM(I17:I18) -> 0 | J16: =SUM(J17:J18) -> 0 | K16: =SUM(K17:K18) -> 0 | L16: =SUM(L17:L18) -> 0
A17: de conducere | E17: 126 | F17: 46273 | G17: ='09881 (TOTAL)'!G17+'14279 (TOTAL)'!G17 -> 0 | H17: ='09881 (TOTAL)'!H17+'14279 (TOTAL)'!H17 -> 0 | I17: ='09881 (TOTAL)'!I17+'14279 (TOTAL)'!I17 -> 0 | J17: ='09881 (TOTAL)'!J17+'14279 (TOTAL)'!J17 -> 0 | K17: =G17 -> 0 | L17: ='09881 (TOTAL)'!L17+'14279 (TOTAL)'!L17 -> 0
A18: de execuție | E18: 145 | F18: 46303 | G18: ='09881 (TOTAL)'!G18+'14279 (TOTAL)'!G18 -> 0 | H18: ='09881 (TOTAL)'!H18+'14279 (TOTAL)'!H18 -> 0 | I18: ='09881 (TOTAL)'!I18+'14279 (TOTAL)'!I18 -> 0 | J18: ='09881 (TOTAL)'!J18+'14279 (TOTAL)'!J18 -> 0 | K18: =G18 -> 0 | L18: ='09881 (TOTAL)'!L18+'14279 (TOTAL)'!L18 -> 0
A19: funcții complexe, inclusiv | E19: 104 | F19: 46334 | G19: =SUM(G20:G22) -> 0 | H19: =SUM(H20:H22) -> 0 | I19: =SUM(I20:I22) -> 0 | J19: =SUM(J20:J22) -> 0 | K19: =SUM(K20:K22) -> 0 | L19: =SUM(L20:L22) -> 0
A20: de conducere | E20: 126 | F20: 46364 | G20: ='09881 (TOTAL)'!G20+'14279 (TOTAL)'!G20 -> 0 | H20: ='09881 (TOTAL)'!H20+'14279 (TOTAL)'!H20 -> 0 | I20: ='09881 (TOTAL)'!I20+'14279 (TOTAL)'!I20 -> 0 | J20: ='09881 (TOTAL)'!J20+'14279 (TOTAL)'!J20 -> 0 | K20: =G20 -> 0 | L20: ='09881 (TOTAL)'!L20+'14279 (TOTAL)'!L20 -> 0
A21: de execuție | E21: 145 | F21: 8.13 | G21: ='09881 (TOTAL)'!G21+'14279 (TOTAL)'!G21 -> 0 | H21: ='09881 (TOTAL)'!H21+'14279 (TOTAL)'!H21 -> 0 | I21: ='09881 (TOTAL)'!I21+'14279 (TOTAL)'!I21 -> 0 | J21: ='09881 (TOTAL)'!J21+'14279 (TOTAL)'!J21 -> 0 | K21: =G21 -> 0 | L21: ='09881 (TOTAL)'!L21+'14279 (TOTAL)'!L21 -> 0
A22: muncitori | E22: 177 | F22: 8.14 | G22: ='09881 (TOTAL)'!G22+'14279 (TOTAL)'!G22 -> 0 | H22: ='09881 (TOTAL)'!H22+'14279 (TOTAL)'!H22 -> 0 | I22: ='09881 (TOTAL)'!I22+'14279 (TOTAL)'!I22 -> 0 | J22: ='09881 (TOTAL)'!J22+'14279 (TOTAL)'!J22 -> 0 | K22: =G22 -> 0 | L22: ='09881 (TOTAL)'!L22+'14279 (TOTAL)'!L22 -> 0
A23: Personal angajat în total, inclusiv | E23: 100 | F23: 8.15 | G23: =G24+G28+G31 -> 0 | H23: =H24+H28+H31 -> 0 | I23: x | J23: =J24+J28+J31 -> 0 | K23: =K24+K28+K31 -> 0 | L23: =L24+L28+L31 -> 0
A24: funcții didactice, inclusiv | E24: 105 | F24: 8.16 | G24: =SUM(G25:G26) -> 0 | H24: =SUM(H25:H26) -> 0 | I24: x | J24: =SUM(J25:J26) -> 0 | K24: =SUM(K25:K26) -> 0 | L24: =SUM(L25:L26) -> 0
A25: de conducere | E25: 120 | F25: 8.17 | G25: ='09881 (TOTAL)'!G25+'14279 (TOTAL)'!G25 -> 0 | H25: ='09881 (TOTAL)'!H25+'14279 (TOTAL)'!H25 -> 0 | I25: x | J25: ='09881 (TOTAL)'!J25+'14279 (TOTAL)'!J25 -> 0 | K25: =G25 -> 0 | L25: ='09881 (TOTAL)'!L25+'14279 (TOTAL)'!L25 -> 0
A26: de execuție, din care | E26: 140 | F26: 8.18 | G26: ='09881 (TOTAL)'!G26+'14279 (TOTAL)'!G26 -> 0 | H26: ='09881 (TOTAL)'!H26+'14279 (TOTAL)'!H26 -> 0 | I26: x | J26: ='09881 (TOTAL)'!J26+'14279 (TOTAL)'!J26 -> 0 | K26: =G26 -> 0 | L26: ='09881 (TOTAL)'!L26+'14279 (TOTAL)'!L26 -> 0
A27: cadre didactice de sprijin | E27: 147 | F27: 8.19 | G27: ='09881 (TOTAL)'!G27+'14279 (TOTAL)'!G27 -> 0 | H27: ='09881 (TOTAL)'!H27+'14279 (TOTAL)'!H27 -> 0 | I27: x | J27: ='09881 (TOTAL)'!J27+'14279 (TOTAL)'!J27 -> 0 | K27: =G27 -> 0 | L27: ='09881 (TOTAL)'!L27+'14279 (TOTAL)'!L27 -> 0
A28: funcții de specialitate, inclusiv | E28: 106 | F28: 8.20 | G28: =SUM(G29:G30) -> 0 | H28: =SUM(H29:H30) -> 0 | I28: x | J28: =SUM(J29:J30) -> 0 | K28: =SUM(K29:K30) -> 0 | L28: =SUM(L29:L30) -> 0
A29: de conducere | E29: 120 | F29: 8.21 | G29: ='09881 (TOTAL)'!G29+'14279 (TOTAL)'!G29 -> 0 | H29: ='09881 (TOTAL)'!H29+'14279 (TOTAL)'!H29 -> 0 | I29: x | J29: ='09881 (TOTAL)'!J29+'14279 (TOTAL)'!J29 -> 0 | K29: =G29 -> 0 | L29: ='09881 (TOTAL)'!L29+'14279 (TOTAL)'!L29 -> 0
A30: de execuție | E30: 140 | F30: 8.22 | G30: ='09881 (TOTAL)'!G30+'14279 (TOTAL)'!G30 -> 0 | H30: ='09881 (TOTAL)'!H30+'14279 (TOTAL)'!H30 -> 0 | I30: x | J30: ='09881 (TOTAL)'!J30+'14279 (TOTAL)'!J30 -> 0 | K30: =G30 -> 0 | L30: ='09881 (TOTAL)'!L30+'14279 (TOTAL)'!L30 -> 0
A31: funcții complexe, inclusiv | E31: 107 | F31: 8.23 | G31: =SUM(G32:G34) -> 0 | H31: =SUM(H32:H34) -> 0 | I31: x | J31: =SUM(J32:J34) -> 0 | K31: =SUM(K32:K34) -> 0 | L31: =SUM(L32:L34) -> 0
A32: de conducere | E32: 120 | F32: 8.24 | G32: ='09881 (TOTAL)'!G32+'14279 (TOTAL)'!G32 -> 0 | H32: ='09881 (TOTAL)'!H32+'14279 (TOTAL)'!H32 -> 0 | I32: x | J32: ='09881 (TOTAL)'!J32+'14279 (TOTAL)'!J32 -> 0 | K32: =G32 -> 0 | L32: ='09881 (TOTAL)'!L32+'14279 (TOTAL)'!L32 -> 0
A33: de execuție | E33: 140 | F33: 8.25 | G33: ='09881 (TOTAL)'!G33+'14279 (TOTAL)'!G33 -> 0 | H33: ='09881 (TOTAL)'!H33+'14279 (TOTAL)'!H33 -> 0 | I33: x | J33: ='09881 (TOTAL)'!J33+'14279 (TOTAL)'!J33 -> 0 | K33: =G33 -> 0 | L33: ='09881 (TOTAL)'!L33+'14279 (TOTAL)'!L33 -> 0
A34: muncitori | E34: 175 | F34: 8.26 | G34: ='09881 (TOTAL)'!G34+'14279 (TOTAL)'!G34 -> 0 | H34: ='09881 (TOTAL)'!H34+'14279 (TOTAL)'!H34 -> 0 | I34: x | J34: ='09881 (TOTAL)'!J34+'14279 (TOTAL)'!J34 -> 0 | K34: =G34 -> 0 | L34: ='09881 (TOTAL)'!L34+'14279 (TOTAL)'!L34 -> 0
A35: Numărul personalului didactic beneficiar de compensații anuale, inclusiv | E35: 108 | F35: 8.27 | G35: =SUM(G36:G37) -> 41 | H35: =SUM(H36:H37) -> 43 | I35: x | J35: x | K35: =SUM(K36:K37) -> 41 | L35: =SUM(L36:L37) -> 42
A36: cu funcție de conducere | E36: 120 | F36: 8.28 | G36: ='09881 (TOTAL)'!G36+'14279 (TOTAL)'!G36 -> 5 | H36: ='09881 (TOTAL)'!H36+'14279 (TOTAL)'!H36 -> 5 | I36: x | J36: x | K36: =G36 -> 5 | L36: ='09881 (TOTAL)'!L36+'14279 (TOTAL)'!L36 -> 5
A37: cu funcție de execuție | E37: 140 | F37: 8.29 | G37: ='09881 (TOTAL)'!G37+'14279 (TOTAL)'!G37 -> 36 | H37: ='09881 (TOTAL)'!H37+'14279 (TOTAL)'!H37 -> 38 | I37: x | J37: x | K37: =G37 -> 36 | L37: ='09881 (TOTAL)'!L37+'14279 (TOTAL)'!L37 -> 37
A38: Retibuirea muncii în total, inclusiv | E38: 500 | F38: 8.30 | G38: x | H38: x | I38: =I39+I43+I46 -> 0 | J38: =J39+J43+J46 -> 0 | K38: x | L38: x
A39: funcții didactice, inclusiv | E39: 501 | F39: 8.31 | G39: x | H39: x | I39: =SUM(I40:I41) -> 0 | J39: =SUM(J40:J41) -> 0 | K39: x | L39: x
A40: de conducere | E40: 510 | F40: 8.32 | G40: x | H40: x | I40: ='09881 (TOTAL)'!I40+'14279 (TOTAL)'!I40 -> 0 | J40: ='09881 (TOTAL)'!J40+'14279 (TOTAL)'!J40 -> 0 | K40: x | L40: x
A41: de execuție, din care | E41: 540 | F41: 8.33 | G41: x | H41: x | I41: ='09881 (TOTAL)'!I41+'14279 (TOTAL)'!I41 -> 0 | J41: ='09881 (TOTAL)'!J41+'14279 (TOTAL)'!J41 -> 0 | K41: x | L41: x
...

Sheet 0912 (00200)
A1: Învățământ primar (Activitatea de bază) | J1: Forma FD-048BL Aprobat prin ordinul Ministrului al Finanțelor al Republicii Moldova nr. _______ al _________
A2: ORG2 | B2: F1F3 | C2: P1P2 | D2: P3
A3: TOTAL | B3: 0912 | C3: 8803 | D3: 00200
A4: REȚEA, STATE ȘI CONTINGENTE ALE INSTITUȚIILOR
A5: ÎN PERIOADA 12 LUNI. 2025
A6: Denumirea indicatorului | E6: CF | F6: CR | G6: Aprobat la începutul anului | H6: Aprobat la sfârșitul anului | I6: Numărul mediu prevazut pe an | J6: Numărul mediu realizat la mm.dd.20__ | K6: Real încadrat la începutul anului | L6: Real încadrat la sfârsitul perioadei
A8: RAPORT nr. 3-8 privind învățămîntul primar, gimnazial și liceal | F8: 8
A9: Instituții în total, inclusiv | E9: 1 | F9: 46030 | I9: x | J9: x | K9: ='0912 (TOTAL)'!K9 -> 2
A10: filiale | E10: 10 | F10: 46061 | G10: ='0912 (TOTAL)'!G10 -> 0 | H10: ='0912 (TOTAL)'!H10 -> 0 | I10: x | J10: x | K10: ='0912 (TOTAL)'!K10 -> 0 | L10: ='0912 (TOTAL)'!L10 -> 0
A11: Unități în state (posturi) în total, inclusiv | E11: 101 | F11: 46089 | G11: =G12+G16+G19 -> 0 | H11: =H12+H16+H19 -> 0 | I11: =I12+I16+I19 -> 0 | J11: =J12+J16+J19 -> 0 | K11: =K12+K16+K19 -> 0 | L11: =L12+L16+L19 -> 0
A12: funcții didactice, inclusiv | E12: 102 | F12: 46120 | G12: =SUM(G13) -> 0 | H12: =SUM(H13:H14) -> 0 | I12: =SUM(I13:I14) -> 0 | J12: =SUM(J13:J14) -> 0 | K12: =SUM(K13:K14) -> 0 | L12: =SUM(L13:L14) -> 0
A13: de conducere | E13: 126 | F13: 46150 | G13: ='0912 (TOTAL)'!G13 -> 0 | H13: ='0912 (TOTAL)'!H13 -> 0 | I13: ='0912 (TOTAL)'!I13 -> 0 | J13: ='0912 (TOTAL)'!J13 -> 0 | K13: ='0912 (TOTAL)'!K13 -> 0 | L13: ='0912 (TOTAL)'!L13 -> 0
A14: de execuție din care | E14: 145 | F14: 46181 | G14: ='0912 (TOTAL)'!G14 -> 0 | H14: ='0912 (TOTAL)'!H14 -> 0 | I14: ='0912 (TOTAL)'!I14 -> 0 | J14: ='0912 (TOTAL)'!J14 -> 0 | K14: ='0912 (TOTAL)'!K14 -> 0 | L14: ='0912 (TOTAL)'!L14 -> 0
A15: cadre didactice de sprijin | E15: 146 | F15: 46211 | G15: ='0912 (TOTAL)'!G15 -> 0 | H15: ='0912 (TOTAL)'!H15 -> 0 | I15: ='0912 (TOTAL)'!I15 -> 0 | J15: ='0912 (TOTAL)'!J15 -> 0 | K15: ='0912 (TOTAL)'!K15 -> 0 | L15: ='0912 (TOTAL)'!L15 -> 0
A16: funcții de specialitate, inclusiv | E16: 103 | F16: 46242 | G16: =SUM(G17:G18) -> 0 | H16: =SUM(H17:H18) -> 0 | I16: =SUM(I17:I18) -> 0 | J16: =SUM(J17:J18) -> 0 | K16: =SUM(K17:K18) -> 0 | L16: =SUM(L17:L18) -> 0
A17: de conducere | E17: 126 | F17: 46273 | G17: ='0912 (TOTAL)'!G17 -> 0 | H17: ='0912 (TOTAL)'!H17 -> 0 | I17: ='0912 (TOTAL)'!I17 -> 0 | J17: ='0912 (TOTAL)'!J17 -> 0 | K17: ='0912 (TOTAL)'!K17 -> 0 | L17: ='0912 (TOTAL)'!L17 -> 0
A18: de execuție | E18: 145 | F18: 46303 | G18: ='0912 (TOTAL)'!G18 -> 0 | H18: ='0912 (TOTAL)'!H18 -> 0 | I18: ='0912 (TOTAL)'!I18 -> 0 | J18: ='0912 (TOTAL)'!J18 -> 0 | K18: ='0912 (TOTAL)'!K18 -> 0 | L18: ='0912 (TOTAL)'!L18 -> 0
A19: funcții complexe, inclusiv | E19: 104 | F19: 46334 | G19: =SUM(G20:G22) -> 0 | H19: =SUM(H20:H22) -> 0 | I19: =SUM(I20:I22) -> 0 | J19: =SUM(J20:J22) -> 0 | K19: =SUM(K20:K22) -> 0 | L19: =SUM(L20:L22) -> 0
A20: de conducere | E20: 126 | F20: 46364 | G20: ='0912 (TOTAL)'!G20 -> 0 | H20: ='0912 (TOTAL)'!H20 -> 0 | I20: ='0912 (TOTAL)'!I20 -> 0 | J20: ='0912 (TOTAL)'!J20 -> 0 | K20: ='0912 (TOTAL)'!K20 -> 0 | L20: ='0912 (TOTAL)'!L20 -> 0
A21: de execuție | E21: 145 | F21: 8.13 | G21: ='0912 (TOTAL)'!G21 -> 0 | H21: ='0912 (TOTAL)'!H21 -> 0 | I21: ='0912 (TOTAL)'!I21 -> 0 | J21: ='0912 (TOTAL)'!J21 -> 0 | K21: ='0912 (TOTAL)'!K21 -> 0 | L21: ='0912 (TOTAL)'!L21 -> 0
A22: muncitori | E22: 177 | F22: 8.14 | G22: ='0912 (TOTAL)'!G22 -> 0 | H22: ='0912 (TOTAL)'!H22 -> 0 | I22: ='0912 (TOTAL)'!I22 -> 0 | J22: ='0912 (TOTAL)'!J22 -> 0 | K22: ='0912 (TOTAL)'!K22 -> 0 | L22: ='0912 (TOTAL)'!L22 -> 0
A23: Personal angajat în total, inclusiv | E23: 100 | F23: 8.15 | G23: =G24+G28+G31 -> 0 | H23: =H24+H28+H31 -> 0 | I23: x | J23: =J24+J28+J31 -> 0 | K23: =K24+K28+K31 -> 0 | L23: =L24+L28+L31 -> 0
A24: funcții didactice, inclusiv | E24: 105 | F24: 8.16 | G24: =SUM(G25:G26) -> 0 | H24: =SUM(H25:H26) -> 0 | I24: x | J24: =SUM(J25:J26) -> 0 | K24: =SUM(K25:K26) -> 0 | L24: =SUM(L25:L26) -> 0
A25: de conducere | E25: 120 | F25: 8.17 | G25: ='0912 (TOTAL)'!G25 -> 0 | H25: ='0912 (TOTAL)'!H25 -> 0 | I25: x | J25: ='0912 (TOTAL)'!J25 -> 0 | K25: ='0912 (TOTAL)'!K25 -> 0 | L25: ='0912 (TOTAL)'!L25 -> 0
A26: de execuție, din care | E26: 140 | F26: 8.18 | G26: ='0912 (TOTAL)'!G26 -> 0 | H26: ='0912 (TOTAL)'!H26 -> 0 | I26: x | J26: ='0912 (TOTAL)'!J26 -> 0 | K26: ='0912 (TOTAL)'!K26 -> 0 | L26: ='0912 (TOTAL)'!L26 -> 0
A27: cadre didactice de sprijin | E27: 147 | F27: 8.19 | G27: ='0912 (TOTAL)'!G27 -> 0 | H27: ='0912 (TOTAL)'!H27 -> 0 | I27: x | J27: ='0912 (TOTAL)'!J27 -> 0 | K27: ='0912 (TOTAL)'!K27 -> 0 | L27: ='0912 (TOTAL)'!L27 -> 0
A28: funcții de specialitate, inclusiv | E28: 106 | F28: 8.20 | G28: =SUM(G29:G30) -> 0 | H28: =SUM(H29:H30) -> 0 | I28: x | J28: =SUM(J29:J30) -> 0 | K28: =SUM(K29:K30) -> 0 | L28: =SUM(L29:L30) -> 0
A29: de conducere | E29: 120 | F29: 8.21 | G29: ='0912 (TOTAL)'!G29 -> 0 | H29: ='0912 (TOTAL)'!H29 -> 0 | I29: x | J29: ='0912 (TOTAL)'!J29 -> 0 | K29: ='0912 (TOTAL)'!K29 -> 0 | L29: ='0912 (TOTAL)'!L29 -> 0
A30: de execuție | E30: 140 | F30: 8.22 | G30: ='0912 (TOTAL)'!G30 -> 0 | H30: ='0912 (TOTAL)'!H30 -> 0 | I30: x | J30: ='0912 (TOTAL)'!J30 -> 0 | K30: ='0912 (TOTAL)'!K30 -> 0 | L30: ='0912 (TOTAL)'!L30 -> 0
A31: funcții complexe, inclusiv | E31: 107 | F31: 8.23 | G31: =SUM(G32:G34) -> 0 | H31: =SUM(H32:H34) -> 0 | I31: x | J31: =SUM(J32:J34) -> 0 | K31: =SUM(K32:K34) -> 0 | L31: =SUM(L32:L34) -> 0
A32: de conducere | E32: 120 | F32: 8.24 | G32: ='0912 (TOTAL)'!G32 -> 0 | H32: ='0912 (TOTAL)'!H32 -> 0 | I32: x | J32: ='0912 (TOTAL)'!J32 -> 0 | K32: ='0912 (TOTAL)'!K32 -> 0 | L32: ='0912 (TOTAL)'!L32 -> 0
A33: de execuție | E33: 140 | F33: 8.25 | G33: ='0912 (TOTAL)'!G33 -> 0 | H33: ='0912 (TOTAL)'!H33 -> 0 | I33: x | J33: ='0912 (TOTAL)'!J33 -> 0 | K33: ='0912 (TOTAL)'!K33 -> 0 | L33: ='0912 (TOTAL)'!L33 -> 0
A34: muncitori | E34: 175 | F34: 8.26 | G34: ='0912 (TOTAL)'!G34 -> 0 | H34: ='0912 (TOTAL)'!H34 -> 0 | I34: x | J34: ='0912 (TOTAL)'!J34 -> 0 | K34: ='0912 (TOTAL)'!K34 -> 0 | L34: ='0912 (TOTAL)'!L34 -> 0
A35: Numărul personalului didactic beneficiar de compensații anuale, inclusiv | E35: 108 | F35: 8.27 | G35: =SUM(G36:G37) -> 0 | H35: =SUM(H36:H37) -> 0 | I35: x | J35: x | K35: =SUM(K36:K37) -> 0 | L35: =SUM(L36:L37) -> 0
A36: cu funcție de conducere | E36: 120 | F36: 8.28 | I36: x | J36: x
A37: cu funcție de execuție | E37: 140 | F37: 8.29 | I37: x | J37: x
A38: Retibuirea muncii în total, inclusiv | E38: 500 | F38: 8.30 | G38: x | H38: x | I38: =I39+I43+I46 -> 0 | J38: =J39+J43+J46 -> 0 | K38: x | L38: x
A39: funcții didactice, inclusiv | E39: 501 | F39: 8.31 | G39: x | H39: x | I39: =SUM(I40:I41) -> 0 | J39: =SUM(J40:J41) -> 0 | K39: x | L39: x
A40: de conducere | E40: 510 | F40: 8.32 | G40: x | H40: x | I40: ='0912 (TOTAL)'!I40 -> 0 | J40: ='0912 (TOTAL)'!J40 -> 0 | K40: x | L40: x
A41: de execuție, din care | E41: 540 | F41: 8.33 | G41: x | H41: x | I41: ='0912 (TOTAL)'!I41 -> 0 | J41: ='0912 (TOTAL)'!J41 -> 0 | K41: x | L41: x
...

Sheet 0912 (00448)
A1: Învățământ primar (Alimentația) | J1: Forma FD-048BL Aprobat prin ordinul Ministrului al Finanțelor al Republicii Moldova nr. _______ al _________
A2: ORG2 | B2: F1F3 | C2: P1P2 | D2: P3
A3: TOTAL | B3: 0912 | C3: 8803 | D3: 00448
A4: REȚEA, STATE ȘI CONTINGENTE ALE INSTITUȚIILOR
A5: ÎN PERIOADA 12 LUNI. 2025
A6: Denumirea indicatorului | E6: CF | F6: CR | G6: Aprobat la începutul anului | H6: Aprobat la sfârșitul anului | I6: Numărul mediu prevazut pe an | J6: Numărul mediu realizat la mm.dd.20__ | K6: Real încadrat la începutul anului | L6: Real încadrat la sfârsitul perioadei
A8: RAPORT nr. 3-8 privind învățămîntul primar, gimnazial și liceal | F8: 8
A9: Instituții în total, inclusiv | E9: 1 | F9: 46030 | I9: x | J9: x
A10: filiale | E10: 10 | F10: 46061 | I10: x | J10: x
A11: Unități în state (posturi) în total, inclusiv | E11: 101 | F11: 46089 | G11: =G12+G16+G19 -> 0 | H11: =H12+H16+H19 -> 0 | I11: =I12+I16+I19 -> 0 | J11: =J12+J16+J19 -> 0 | K11: =K12+K16+K19 -> 0 | L11: =L12+L16+L19 -> 0
A12: funcții didactice, inclusiv | E12: 102 | F12: 46120 | G12: =SUM(G13:G14) -> 0 | H12: =SUM(H13:H14) -> 0 | I12: =SUM(I13:I14) -> 0 | J12: =SUM(J13:J14) -> 0 | K12: =SUM(K13:K14) -> 0 | L12: =SUM(L13:L14) -> 0
A13: de conducere | E13: 126 | F13: 46150
A14: de execuție din care | E14: 145 | F14: 46181
A15: cadre didactice de sprijin | E15: 146 | F15: 46211
A16: funcții de specialitate, inclusiv | E16: 103 | F16: 46242 | G16: =SUM(G17:G18) -> 0 | H16: =SUM(H17:H18) -> 0 | I16: =SUM(I17:I18) -> 0 | J16: =SUM(J17:J18) -> 0 | K16: =SUM(K17:K18) -> 0 | L16: =SUM(L17:L18) -> 0
A17: de conducere | E17: 126 | F17: 46273
A18: de execuție | E18: 145 | F18: 46303
A19: funcții complexe, inclusiv | E19: 104 | F19: 46334 | G19: =SUM(G20:G22) -> 0 | H19: =SUM(H20:H22) -> 0 | I19: =SUM(I20:I22) -> 0 | J19: =SUM(J20:J22) -> 0 | K19: =SUM(K20:K22) -> 0 | L19: =SUM(L20:L22) -> 0
A20: de conducere | E20: 126 | F20: 46364
A21: de execuție | E21: 145 | F21: 8.13
A22: muncitori | E22: 177 | F22: 8.14
A23: Personal angajat în total, inclusiv | E23: 100 | F23: 8.15 | G23: =G24+G28+G31 -> 0 | H23: =H24+H28+H31 -> 0 | I23: x | J23: =J24+J28+J31 -> 0 | K23: =K24+K28+K31 -> 0 | L23: =L24+L28+L31 -> 0
A24: funcții didactice, inclusiv | E24: 105 | F24: 8.16 | G24: =SUM(G25:G26) -> 0 | H24: =SUM(H25:H26) -> 0 | I24: x | J24: =SUM(J25:J26) -> 0 | K24: =SUM(K25:K26) -> 0 | L24: =SUM(L25:L26) -> 0
A25: de conducere | E25: 120 | F25: 8.17 | I25: x
A26: de execuție, din care | E26: 140 | F26: 8.18 | I26: x
A27: cadre didactice de sprijin | E27: 147 | F27: 8.19 | I27: x
A28: funcții de specialitate, inclusiv | E28: 106 | F28: 8.20 | G28: =SUM(G29:G30) -> 0 | H28: =SUM(H29:H30) -> 0 | I28: x | J28: =SUM(J29:J30) -> 0 | K28: =SUM(K29:K30) -> 0 | L28: =SUM(L29:L30) -> 0
A29: de conducere | E29: 120 | F29: 8.21 | I29: x
A30: de execuție | E30: 140 | F30: 8.22 | I30: x
A31: funcții complexe, inclusiv | E31: 107 | F31: 8.23 | G31: =SUM(G32:G34) -> 0 | H31: =SUM(H32:H34) -> 0 | I31: x | J31: =SUM(J32:J34) -> 0 | K31: =SUM(K32:K34) -> 0 | L31: =SUM(L32:L34) -> 0
A32: de conducere | E32: 120 | F32: 8.24 | I32: x
A33: de execuție | E33: 140 | F33: 8.25 | I33: x
A34: muncitori | E34: 175 | F34: 8.26 | I34: x
A35: Numărul personalului didactic beneficiar de compensații anuale, inclusiv | E35: 108 | F35: 8.27 | G35: =SUM(G36:G37) -> 0 | H35: =SUM(H36:H37) -> 0 | I35: x | J35: x | K35: =SUM(K36:K37) -> 0 | L35: =SUM(L36:L37) -> 0
A36: cu funcție de conducere | E36: 120 | F36: 8.28 | I36: x | J36: x
A37: cu funcție de execuție | E37: 140 | F37: 8.29 | I37: x | J37: x
A38: Retibuirea muncii în total, inclusiv | E38: 500 | F38: 8.30 | G38: x | H38: x | I38: =I39+I43+I46 -> 0 | J38: =J39+J43+J46 -> 0 | K38: x | L38: x
A39: funcții didactice, inclusiv | E39: 501 | F39: 8.31 | G39: x | H39: x | I39: =SUM(I40:I41) -> 0 | J39: =SUM(J40:J41) -> 0 | K39: x | L39: x
A40: de conducere | E40: 510 | F40: 8.32 | G40: x | H40: x | K40: x | L40: x
A41: de execuție, din care | E41: 540 | F41: 8.33 | G41: x | H41: x | K41: x | L41: x
...

Sheet 0912 (00492)
A1: Învățământ primar (Compensații) | J1: Forma FD-048BL Aprobat prin ordinul Ministrului al Finanțelor al Republicii Moldova nr. _______ al _________
A2: ORG2 | B2: F1F3 | C2: P1P2 | D2: P3
A3: TOTAL | B3: 0912 | C3: 8803 | D3: 00492
A4: REȚEA, STATE ȘI CONTINGENTE ALE INSTITUȚIILOR
A5: ÎN PERIOADA 12 LUNI. 2025
A6: Denumirea indicatorului | E6: CF | F6: CR | G6: Aprobat la începutul anului | H6: Aprobat la sfârșitul anului | I6: Numărul mediu prevazut pe an | J6: Numărul mediu realizat la mm.dd.20__ | K6: Real încadrat la începutul anului | L6: Real încadrat la sfârsitul perioadei
A8: RAPORT nr. 3-8 privind învățămîntul primar, gimnazial și liceal | F8: 8
A9: Instituții în total, inclusiv | E9: 1 | F9: 46030 | I9: x | J9: x
A10: filiale | E10: 10 | F10: 46061 | I10: x | J10: x
A11: Unități în state (posturi) în total, inclusiv | E11: 101 | F11: 46089 | G11: =G12+G16+G19 -> 0 | H11: =H12+H16+H19 -> 0 | I11: =I12+I16+I19 -> 0 | J11: =J12+J16+J19 -> 0 | K11: =K12+K16+K19 -> 0 | L11: =L12+L16+L19 -> 0
A12: funcții didactice, inclusiv | E12: 102 | F12: 46120 | G12: =SUM(G13:G14) -> 0 | H12: =SUM(H13:H14) -> 0 | I12: =SUM(I13:I14) -> 0 | J12: =SUM(J13:J14) -> 0 | K12: =SUM(K13:K14) -> 0 | L12: =SUM(L13:L14) -> 0
A13: de conducere | E13: 126 | F13: 46150
A14: de execuție din care | E14: 145 | F14: 46181
A15: cadre didactice de sprijin | E15: 146 | F15: 46211
A16: funcții de specialitate, inclusiv | E16: 103 | F16: 46242 | G16: =SUM(G17:G18) -> 0 | H16: =SUM(H17:H18) -> 0 | I16: =SUM(I17:I18) -> 0 | J16: =SUM(J17:J18) -> 0 | K16: =SUM(K17:K18) -> 0 | L16: =SUM(L17:L18) -> 0
A17: de conducere | E17: 126 | F17: 46273
A18: de execuție | E18: 145 | F18: 46303
A19: funcții complexe, inclusiv | E19: 104 | F19: 46334 | G19: =SUM(G20:G22) -> 0 | H19: =SUM(H20:H22) -> 0 | I19: =SUM(I20:I22) -> 0 | J19: =SUM(J20:J22) -> 0 | K19: =SUM(K20:K22) -> 0 | L19: =SUM(L20:L22) -> 0
A20: de conducere | E20: 126 | F20: 46364
A21: de execuție | E21: 145 | F21: 8.13
A22: muncitori | E22: 177 | F22: 8.14
A23: Personal angajat în total, inclusiv | E23: 100 | F23: 8.15 | G23: =G24+G28+G31 -> 0 | H23: =H24+H28+H31 -> 0 | I23: x | J23: =J24+J28+J31 -> 0 | K23: =K24+K28+K31 -> 0 | L23: =L24+L28+L31 -> 0
A24: funcții didactice, inclusiv | E24: 105 | F24: 8.16 | G24: =SUM(G25:G26) -> 0 | H24: =SUM(H25:H26) -> 0 | I24: x | J24: =SUM(J25:J26) -> 0 | K24: =SUM(K25:K26) -> 0 | L24: =SUM(L25:L26) -> 0
A25: de conducere | E25: 120 | F25: 8.17 | I25: x
A26: de execuție, din care | E26: 140 | F26: 8.18 | I26: x
A27: cadre didactice de sprijin | E27: 147 | F27: 8.19 | I27: x
A28: funcții de specialitate, inclusiv | E28: 106 | F28: 8.20 | G28: =SUM(G29:G30) -> 0 | H28: =SUM(H29:H30) -> 0 | I28: x | J28: =SUM(J29:J30) -> 0 | K28: =SUM(K29:K30) -> 0 | L28: =SUM(L29:L30) -> 0
A29: de conducere | E29: 120 | F29: 8.21 | I29: x
A30: de execuție | E30: 140 | F30: 8.22 | I30: x
A31: funcții complexe, inclusiv | E31: 107 | F31: 8.23 | G31: =SUM(G32:G34) -> 0 | H31: =SUM(H32:H34) -> 0 | I31: x | J31: =SUM(J32:J34) -> 0 | K31: =SUM(K32:K34) -> 0 | L31: =SUM(L32:L34) -> 0
A32: de conducere | E32: 120 | F32: 8.24 | I32: x
A33: de execuție | E33: 140 | F33: 8.25 | I33: x
A34: muncitori | E34: 175 | F34: 8.26 | I34: x
A35: Numărul personalului didactic beneficiar de compensații anuale, inclusiv | E35: 108 | F35: 8.27 | G35: =SUM(G36:G37) -> 41 | H35: =SUM(H36:H37) -> 43 | I35: x | J35: x | K35: =SUM(K36:K37) -> 41 | L35: =SUM(L36:L37) -> 42
A36: cu funcție de conducere | E36: 120 | F36: 8.28 | G36: ='0912 (TOTAL)'!G36 -> 5 | H36: ='0912 (TOTAL)'!H36 -> 5 | I36: x | J36: x | K36: ='0912 (TOTAL)'!K36 -> 5 | L36: ='0912 (TOTAL)'!L36 -> 5
A37: cu funcție de execuție | E37: 140 | F37: 8.29 | G37: ='0912 (TOTAL)'!G37 -> 36 | H37: ='0912 (TOTAL)'!H37 -> 38 | I37: x | J37: x | K37: ='0912 (TOTAL)'!K37 -> 36 | L37: ='0912 (TOTAL)'!L37 -> 37
A38: Retibuirea muncii în total, inclusiv | E38: 500 | F38: 8.30 | G38: x | H38: x | I38: =I39+I43+I46 -> 0 | J38: =J39+J43+J46 -> 0 | K38: x | L38: x
A39: funcții didactice, inclusiv | E39: 501 | F39: 8.31 | G39: x | H39: x | I39: =SUM(I40:I41) -> 0 | J39: =SUM(J40:J41) -> 0 | K39: x | L39: x
A40: de conducere | E40: 510 | F40: 8.32 | G40: x | H40: x | K40: x | L40: x
A41: de execuție, din care | E41: 540 | F41: 8.33 | G41: x | H41: x | K41: x | L41: x
...

Sheet 09881 (TOTAL)
A1: Școala primara nr. 21 | J1: Forma FD-048BL Aprobat prin ordinul Ministrului al Finanțelor al Republicii Moldova nr. _______ al _________
A2: ORG2 | B2: F1F3 | C2: P1P2 | D2: P3
A3: 09881 | B3: 0912 | C3: 8803 | D3: TOTAL
A4: REȚEA, STATE ȘI CONTINGENTE ALE INSTITUȚIILOR
A5: ÎN PERIOADA 12 LUNI. 2025
A6: Denumirea indicatorului | E6: CF | F6: CR | G6: Aprobat la începutul anului | H6: Aprobat la sfârșitul anului | I6: Numărul mediu prevazut pe an | J6: Numărul mediu realizat la mm.dd.20__ | K6: Real încadrat la începutul anului | L6: Real încadrat la sfârsitul perioadei
A8: RAPORT nr. 3-8 privind învățămîntul primar, gimnazial și liceal | F8: 8
A9: Instituții în total, inclusiv | E9: 1 | F9: 46030 | G9: 1 | H9: 1 | I9: x | J9: x | K9: =H9 -> 1 | L9: 1
A10: filiale | E10: 10 | F10: 46061 | I10: x | J10: x | K10: =G10
A11: Unități în state (posturi) în total, inclusiv | E11: 101 | F11: 46089 | G11: =G12+G16+G19 -> 0 | H11: =H12+H16+H19 -> 0 | I11: =I12+I16+I19 -> 0 | J11: =J12+J16+J19 -> 0 | K11: =K12+K16+K19 -> 0 | L11: =L12+L16+L19 -> 0
A12: funcții didactice, inclusiv | E12: 102 | F12: 46120 | G12: =SUM(G13:G14) -> 0 | H12: =SUM(H13:H14) -> 0 | I12: =SUM(I13:I14) -> 0 | J12: =SUM(J13:J14) -> 0 | K12: =SUM(K13:K14) -> 0 | L12: =SUM(L13:L14) -> 0
A13: de conducere | E13: 126 | F13: 46150 | K13: =G13
A14: de execuție din care | E14: 145 | F14: 46181 | K14: =G14
A15: cadre didactice de sprijin | E15: 146 | F15: 46211 | K15: =G15
A16: funcții de specialitate, inclusiv | E16: 103 | F16: 46242 | G16: =SUM(G17:G18) -> 0 | H16: =SUM(H17:H18) -> 0 | I16: =SUM(I17:I18) -> 0 | J16: =SUM(J17:J18) -> 0 | K16: =SUM(K17:K18) -> 0 | L16: =SUM(L17:L18) -> 0
A17: de conducere | E17: 126 | F17: 46273 | K17: =G17
A18: de execuție | E18: 145 | F18: 46303 | K18: =G18
A19: funcții complexe, inclusiv | E19: 104 | F19: 46334 | G19: =SUM(G20:G22) -> 0 | H19: =SUM(H20:H22) -> 0 | I19: =SUM(I20:I22) -> 0 | J19: =SUM(J20:J22) -> 0 | K19: =SUM(K20:K22) -> 0 | L19: =SUM(L20:L22) -> 0
A20: de conducere | E20: 126 | F20: 46364 | K20: =G20
A21: de execuție | E21: 145 | F21: 8.13 | K21: =G21
A22: muncitori | E22: 177 | F22: 8.14 | K22: =G22
A23: Personal angajat în total, inclusiv | E23: 100 | F23: 8.15 | G23: =G24+G28+G31 -> 0 | H23: =H24+H28+H31 -> 0 | I23: x | J23: =J24+J28+J31 -> 0 | K23: =K24+K28+K31 -> 0 | L23: =L24+L28+L31 -> 0
A24: funcții didactice, inclusiv | E24: 105 | F24: 8.16 | G24: =SUM(G25:G26) -> 0 | H24: =SUM(H25:H26) -> 0 | I24: x | J24: =SUM(J25:J26) -> 0 | K24: =SUM(K25:K26) -> 0 | L24: =SUM(L25:L26) -> 0
A25: de conducere | E25: 120 | F25: 8.17 | I25: x | K25: =G25
A26: de execuție, din care | E26: 140 | F26: 8.18 | I26: x | K26: =G26
A27: cadre didactice de sprijin | E27: 147 | F27: 8.19 | I27: x | K27: =G27
A28: funcții de specialitate, inclusiv | E28: 106 | F28: 8.20 | G28: =SUM(G29:G30) -> 0 | H28: =SUM(H29:H30) -> 0 | I28: x | J28: =SUM(J29:J30) -> 0 | K28: =SUM(K29:K30) -> 0 | L28: =SUM(L29:L30) -> 0
A29: de conducere | E29: 120 | F29: 8.21 | I29: x | K29: =G29
A30: de execuție | E30: 140 | F30: 8.22 | I30: x | K30: =G30
A31: funcții complexe, inclusiv | E31: 107 | F31: 8.23 | G31: =SUM(G32:G34) -> 0 | H31: =SUM(H32:H34) -> 0 | I31: x | J31: =SUM(J32:J34) -> 0 | K31: =SUM(K32:K34) -> 0 | L31: =SUM(L32:L34) -> 0
A32: de conducere | E32: 120 | F32: 8.24 | I32: x | K32: =G32
A33: de execuție | E33: 140 | F33: 8.25 | I33: x | K33: =G33
A34: muncitori | E34: 175 | F34: 8.26 | I34: x | K34: =G34
A35: Numărul personalului didactic beneficiar de compensații anuale, inclusiv | E35: 108 | F35: 8.27 | G35: =SUM(G36:G37) -> 36 | H35: =SUM(H36:H37) -> 38 | I35: x | J35: x | K35: =SUM(K36:K37) -> 36 | L35: =SUM(L36:L37) -> 37
A36: cu funcție de conducere | E36: 120 | F36: 8.28 | G36: 4 | H36: 4 | I36: x | J36: x | K36: =G36 -> 4 | L36: 4
A37: cu funcție de execuție | E37: 140 | F37: 8.29 | G37: 32 | H37: 34 | I37: x | J37: x | K37: =G37 -> 32 | L37: 33
A38: Retibuirea muncii în total, inclusiv | E38: 500 | F38: 8.30 | G38: x | H38: x | I38: =I39+I43+I46 -> 0 | J38: =J39+J43+J46 -> 0 | K38: x | L38: x
A39: funcții didactice, inclusiv | E39: 501 | F39: 8.31 | G39: x | H39: x | I39: =SUM(I40:I41) -> 0 | J39: =SUM(J40:J41) -> 0 | K39: x | L39: x
A40: de conducere | E40: 510 | F40: 8.32 | G40: x | H40: x | K40: x | L40: x
A41: de execuție, din care | E41: 540 | F41: 8.33 | G41: x | H41: x | K41: x | L41: x
...

Sheet 09881 (00200)
A1: Școala primara nr. 21 (Activitatea de bază) | J1: Forma FD-048BL Aprobat prin ordinul Ministrului al Finanțelor al Republicii Moldova nr. _______ al _________
A2: ORG2 | B2: F1F3 | C2: P1P2 | D2: P3
A3: 09881 | B3: 0912 | C3: 8803 | D3: 00200
A4: REȚEA, STATE ȘI CONTINGENTE ALE INSTITUȚIILOR
A5: ÎN PERIOADA 12 LUNI. 2025
A6: Denumirea indicatorului | E6: CF | F6: CR | G6: Aprobat la începutul anului | H6: Aprobat la sfârșitul anului | I6: Numărul mediu prevazut pe an | J6: Numărul mediu realizat la mm.dd.20__ | K6: Real încadrat la începutul anului | L6: Real încadrat la sfârsitul perioadei
A8: RAPORT nr. 3-8 privind învățămîntul primar, gimnazial și liceal | F8: 8
A9: Instituții în total, inclusiv | E9: 1 | F9: 46030 | G9: ='09881 (TOTAL)'!G9 -> 1 | H9: ='09881 (TOTAL)'!H9 -> 1 | I9: x | J9: x | K9: ='09881 (TOTAL)'!K9 -> 1 | L9: ='09881 (TOTAL)'!L9 -> 1
A10: filiale | E10: 10 | F10: 46061 | G10: ='09881 (TOTAL)'!G10 | H10: ='09881 (TOTAL)'!H10 | I10: x | J10: x | K10: ='09881 (TOTAL)'!K10 | L10: ='09881 (TOTAL)'!L10
A11: Unități în state (posturi) în total, inclusiv | E11: 101 | F11: 46089 | G11: =G12+G16+G19 -> 0 | H11: =H12+H16+H19 -> 0 | I11: =I12+I16+I19 -> 0 | J11: =J12+J16+J19 -> 0 | K11: =K12+K16+K19 -> 0 | L11: =L12+L16+L19 -> 0
A12: funcții didactice, inclusiv | E12: 102 | F12: 46120 | G12: =SUM(G13) -> 0 | H12: =SUM(H13:H14) -> 0 | I12: =SUM(I13:I14) -> 0 | J12: =SUM(J13:J14) -> 0 | K12: =SUM(K13:K14) -> 0 | L12: =SUM(L13:L14) -> 0
A13: de conducere | E13: 126 | F13: 46150 | G13: ='09881 (TOTAL)'!G13 | H13: ='09881 (TOTAL)'!H13 | I13: ='09881 (TOTAL)'!I13 | J13: ='09881 (TOTAL)'!J13 | K13: ='09881 (TOTAL)'!K13 | L13: ='09881 (TOTAL)'!L13
A14: de execuție din care | E14: 145 | F14: 46181 | G14: ='09881 (TOTAL)'!G14 | H14: ='09881 (TOTAL)'!H14 | I14: ='09881 (TOTAL)'!I14 | J14: ='09881 (TOTAL)'!J14 | K14: ='09881 (TOTAL)'!K14 | L14: ='09881 (TOTAL)'!L14
A15: cadre didactice de sprijin | E15: 146 | F15: 46211 | G15: ='09881 (TOTAL)'!G15 | H15: ='09881 (TOTAL)'!H15 | I15: ='09881 (TOTAL)'!I15 | J15: ='09881 (TOTAL)'!J15 | K15: ='09881 (TOTAL)'!K15 | L15: ='09881 (TOTAL)'!L15
A16: funcții de specialitate, inclusiv | E16: 103 | F16: 46242 | G16: =SUM(G17:G18) -> 0 | H16: =SUM(H17:H18) -> 0 | I16: =SUM(I17:I18) -> 0 | J16: =SUM(J17:J18) -> 0 | K16: =SUM(K17:K18) -> 0 | L16: =SUM(L17:L18) -> 0
A17: de conducere | E17: 126 | F17: 46273 | G17: ='09881 (TOTAL)'!G17 | H17: ='09881 (TOTAL)'!H17 | I17: ='09881 (TOTAL)'!I17 | J17: ='09881 (TOTAL)'!J17 | K17: ='09881 (TOTAL)'!K17 | L17: ='09881 (TOTAL)'!L17
A18: de execuție | E18: 145 | F18: 46303 | G18: ='09881 (TOTAL)'!G18 | H18: ='09881 (TOTAL)'!H18 | I18: ='09881 (TOTAL)'!I18 | J18: ='09881 (TOTAL)'!J18 | K18: ='09881 (TOTAL)'!K18 | L18: ='09881 (TOTAL)'!L18
A19: funcții complexe, inclusiv | E19: 104 | F19: 46334 | G19: =SUM(G20:G22) -> 0 | H19: =SUM(H20:H22) -> 0 | I19: =SUM(I20:I22) -> 0 | J19: =SUM(J20:J22) -> 0 | K19: =SUM(K20:K22) -> 0 | L19: =SUM(L20:L22) -> 0
A20: de conducere | E20: 126 | F20: 46364 | G20: ='09881 (TOTAL)'!G20 | H20: ='09881 (TOTAL)'!H20 | I20: ='09881 (TOTAL)'!I20 | J20: ='09881 (TOTAL)'!J20 | K20: ='09881 (TOTAL)'!K20 | L20: ='09881 (TOTAL)'!L20
A21: de execuție | E21: 145 | F21: 8.13 | G21: ='09881 (TOTAL)'!G21 | H21: ='09881 (TOTAL)'!H21 | I21: ='09881 (TOTAL)'!I21 | J21: ='09881 (TOTAL)'!J21 | K21: ='09881 (TOTAL)'!K21 | L21: ='09881 (TOTAL)'!L21
A22: muncitori | E22: 177 | F22: 8.14 | G22: ='09881 (TOTAL)'!G22 | H22: ='09881 (TOTAL)'!H22 | I22: ='09881 (TOTAL)'!I22 | J22: ='09881 (TOTAL)'!J22 | K22: ='09881 (TOTAL)'!K22 | L22: ='09881 (TOTAL)'!L22
