Workbook

Sheet Total sc.prim
I1: total sc prim
A3: Aprobat prin ordinul Ministrului
A4: al Finanţelor al Republicii Moldova
A5: nr.___________al___________
A6: Retea, state si contingente ale instituriilor
A7: în perioada Tr.2 -2024 | J7: FD-048-BL
A8: Denumirea indicatorului | B8: codificatorul formularului | C8: Codul rindului | D8: Aprobat la inceputul anului | E8: Aprobat la sfirsitul anului | F8: Numarul mediu prevazut pe an | G8: Numarul mediu realizat la 30.09.2025 | H8: Real incadrat la începutul anului | I8: Real incadrat la sfîrsitul perioadei | M8: 00492
A9: 1 | B9: 2 | C9: 3 | D9: 4 | E9: 5 | F9: 6 | G9: 7 | H9: 8 | I9: 9
A10: RAPORT nr. 3-8 privind învățămîntul primar, gimnazial și liceal | C10: 8
A11: Instituții în total, inclusiv | B11: 1 | C11: 8.1 | F11: x | G11: x
A12: filiale | B12: 10 | C12: 8.2 | F12: x | G12: x
A13: Unități în state (posturi) în total, inclusiv | B13: 101 | C13: 8.3 | K13: Aprobat la inceputul anului | L13: Aprobat la sfirsitul anului | M13: Numarul mediu prevazut pe an | N13: Numarul mediu realizat la 01.01.2020 | O13: Real incadrat la începutul anului | P13: Real incadratla sfîrsitul perioadei
A14: funcții didactice, inclusiv | B14: 102 | C14: 8.4 | J14: cond. | K14: =D15+D19+D22 -> 0 | L14: =E15+E19+E22 -> 0 | M14: =F15+F19+F22 -> 0 | N14: =G15+G19+G22 -> 0 | O14: =H15+H19+H22 -> 0 | P14: =I15+I19+I22 -> 0
A15: de conducere | B15: 126 | C15: 8.5 | J15: exec | K15: =D16+D20+D23 -> 0 | L15: =E16+E20+E23 -> 0 | M15: =F16+F20+F23 -> 0 | N15: =G16+G20+G23 -> 0 | O15: =H16+H20+H23 -> 0 | P15: =I16+I20+I23 -> 0
A16: de execuție din care | B16: 145 | C16: 8.6 | J16: muncitori | K16: =D24 -> 0 | L16: =E24 -> 0 | M16: =F24 -> 0 | N16: =G24 -> 0 | O16: =H24 -> 0 | P16: =I24 -> 0
A17: cadre didactice de sprijin | B17: 146 | C17: 8.7 | J17: Total | K17: =K14+K15+K16 -> 0 | L17: =L14+L15+L16 -> 0 | M17: =M14+M15+M16 -> 0 | N17: =N14+N15+N16 -> 0 | O17: =O14+O15+O16 -> 0 | P17: =P14+P15+P16 -> 0
A18: funcții de specialitate, inclusiv | B18: 103 | C18: 8.8 | J18: control | K18: =D13-K17 -> 0 | L18: =E13-L17 -> 0 | M18: =F13-M17 -> 0 | N18: =G13-N17 -> 0 | O18: =H13-O17 -> 0 | P18: =I13-P17 -> 0
A19: de conducere | B19: 126 | C19: 8.9 | J19: 48-BL | K19: 67.49 | L19: 69.8 | M19: 67.8 | N19: 66.5 | O19: 67.49 | P19: 69.39
A20: de execuție | B20: 145 | C20: 8.10 | J20: control | K20: =K17-K19 -> -67.49 | L20: =L17-L19 -> -69.8 | M20: =M17-M19 -> -67.8 | N20: =N17-N19 -> -66.5 | O20: =O17-O19 -> -67.49 | P20: =P17-P19 -> -69.39
A21: funcții complexe, inclusiv | B21: 104 | C21: 8.11
A22: de conducere | B22: 126 | C22: 8.12
A23: de execuție | B23: 145 | C23: 8.13
A24: muncitori | B24: 177 | C24: 8.14
A25: Personal angajat în total, inclusiv | B25: 100 | C25: 8.15 | D25: =D26+D30+D33 -> 0 | E25: =E26+E30+E33 -> 0 | F25: x | G25: =G26+G30+G33 -> 0 | H25: =H26+H30+H33 -> 0 | I25: =I26+I30+I33 -> 0 | K25: Aprobat la inceputul anului | L25: Aprobat la sfirsitul anului | M25: Numarul mediu prevazut pe an | N25: Numarul mediu realizat la 01.01.2020 | O25: Real incadrat la începutul anului | P25: Real incadratla sfîrsitul perioadei
A26: funcții didactice, inclusiv | B26: 105 | C26: 8.16 | F26: x | J26: cond. | K26: =D27+D31+D34 -> 0 | L26: =E27+E31+E34 -> 0 | M26: =F27+F31+F34 -> #VALUE! | N26: =G27+G31+G34 -> 0 | O26: =H27+H31+H34 -> 0 | P26: =I27+I31+I34 -> 0
A27: de conducere | B27: 120 | C27: 8.17 | F27: x | J27: exec | K27: =D28+D32+D35 -> 0 | L27: =E28+E32+E35 -> 0 | M27: =F28+F32+F35 -> #VALUE! | N27: =G28+G32+G35 -> 0 | O27: =H28+H32+H35 -> 0 | P27: =I28+I32+I35 -> 0
A28: de execuție, din care | B28: 140 | C28: 8.18 | F28: x | J28: muncitori | K28: =D36 -> 0 | L28: =E36 -> 0 | M28: =F36 -> x | N28: =G36 -> 0 | O28: =H36 -> 0 | P28: =I36 -> 0
A29: cadre didactice de sprijin | B29: 147 | C29: 8.19 | F29: x | J29: Total | K29: =K26+K27+K28 -> 0 | L29: =L26+L27+L28 -> 0 | M29: =M26+M27+M28 -> #VALUE! | N29: =N26+N27+N28 -> 0 | O29: =O26+O27+O28 -> 0 | P29: =P26+P27+P28 -> 0
A30: funcții de specialitate, inclusiv | B30: 106 | C30: 8.20 | F30: x | J30: control | K30: =K29-D25 -> 0 | L30: =L29-E25 -> 0 | M30: =M29-F25 -> #VALUE! | N30: =N29-G25 -> 0 | O30: =O29-H25 -> 0 | P30: =P29-I25 -> 0
A31: de conducere | B31: 120 | C31: 8.21 | F31: x | J31: 48-BL | K31: 61 | L31: 64 | M31: X | N31: 59 | O31: 61 | P31: 65
A32: de execuție | B32: 140 | C32: 8.22 | F32: x | J32: control | K32: =K29-K31 -> -61 | L32: =L29-L31 -> -64 | M32: =M29-M31 -> #VALUE! | N32: =N29-N31 -> -59 | O32: =O29-O31 -> -61 | P32: =P29-P31 -> -65
A33: funcții complexe, inclusiv | B33: 107 | C33: 8.23 | F33: x
A34: de conducere | B34: 120 | C34: 8.24 | F34: x
A35: de execuție | B35: 140 | C35: 8.25 | F35: x
A36: muncitori | B36: 175 | C36: 8.26 | F36: x
A37: Numărul personalului didactic beneficiar de compensații anuale, inclusiv | B37: 108 | C37: 8.27 | D37: =D38+D39 -> 41 | E37: =E38+E39 -> 43 | F37: x | G37: x | H37: =H38+H39 -> 41 | I37: =I38+I39 -> 43
A38: cu funcție de conducere | B38: 120 | C38: 8.28 | D38: ='sc.prim.16'!D38+scprim.21!D38 -> 5 | E38: ='sc.prim.16'!E38+scprim.21!E38 -> 5 | F38: x | G38: x | H38: =D38 -> 5 | I38: ='sc.prim.16'!I38+scprim.21!I38 -> 5
A39: cu funcție de execuție | B39: 140 | C39: 8.29 | D39: ='sc.prim.16'!D39+scprim.21!D39 -> 36 | E39: ='sc.prim.16'!E39+scprim.21!E39 -> 38 | F39: x | G39: x | H39: =D39 -> 36 | I39: ='sc.prim.16'!I39+scprim.21!I39 -> 38
A40: Retibuirea muncii în total, inclusiv | B40: 500 | C40: 8.30 | D40: x | E40: x | F40: =F41+F45+F48 -> 0 | G40: =G41+G45+G48 -> 0 | H40: x | I40: x
A41: funcții didactice, inclusiv | B41: 501 | C41: 8.31 | D41: x | E41: x | H41: x | I41: x
...

Sheet sc.prim.16
H2: sc prim 16
A3: Aprobat prin ordinul Ministrului
A4: al Finanţelor al Republicii Moldova
A5: nr.___________al___________
A6: Retea, state si contingente ale instituriilor
A7: în perioada Tr.2 -2024 | J7: FD-048-BL
A8: Denumirea indicatorului | B8: codificatorul formularului | C8: Codul rindului | D8: Aprobat la inceputul anului | E8: Aprobat la sfirsitul anului | F8: Numarul mediu prevazut pe an | G8: Numarul mediu realizat la 30.09.2025 | H8: Real incadrat la începutul anului | I8: Real incadrat la sfîrsitul perioadei | J8: 14279 | K8: 0912 | L8: 8803 | M8: 00492 | N8: 0300
A9: 1 | B9: 2 | C9: 3 | D9: 4 | E9: 5 | F9: 6 | G9: 7 | H9: 8 | I9: 9
A10: RAPORT nr. 3-8 privind învățămîntul primar, gimnazial și liceal | C10: 8
A11: Instituții în total, inclusiv | B11: 1 | C11: 8.1 | F11: x | G11: x
A12: filiale | B12: 10 | C12: 8.2 | F12: x | G12: x
A13: Unități în state (posturi) în total, inclusiv | B13: 101 | C13: 8.3 | K13: Aprobat la inceputul anului | L13: Aprobat la sfirsitul anului | M13: Numarul mediu prevazut pe an | N13: Numarul mediu realizat la 01.01.2020 | O13: Real incadrat la începutul anului | P13: Real incadratla sfîrsitul perioadei
A14: funcții didactice, inclusiv | B14: 102 | C14: 8.4 | J14: cond. | K14: =D15+D19+D22 -> 0 | L14: =E15+E19+E22 -> 0 | M14: =F15+F19+F22 -> 0 | N14: =G15+G19+G22 -> 0 | O14: =H15+H19+H22 -> 0 | P14: =I15+I19+I22 -> 0
A15: de conducere | B15: 126 | C15: 8.5 | J15: exec | K15: =D16+D20+D23 -> 0 | L15: =E16+E20+E23 -> 0 | M15: =F16+F20+F23 -> 0 | N15: =G16+G20+G23 -> 0 | O15: =H16+H20+H23 -> 0 | P15: =I16+I20+I23 -> 0
A16: de execuție din care | B16: 145 | C16: 8.6 | J16: muncitori | K16: =D24 -> 0 | L16: =E24 -> 0 | M16: =F24 -> 0 | N16: =G24 -> 0 | O16: =H24 -> 0 | P16: =I24 -> 0
A17: cadre didactice de sprijin | B17: 146 | C17: 8.7 | J17: Total | K17: =K14+K15+K16 -> 0 | L17: =L14+L15+L16 -> 0 | M17: =M14+M15+M16 -> 0 | N17: =N14+N15+N16 -> 0 | O17: =O14+O15+O16 -> 0 | P17: =P14+P15+P16 -> 0
A18: funcții de specialitate, inclusiv | B18: 103 | C18: 8.8 | J18: control | K18: =D13-K17 -> 0 | L18: =E13-L17 -> 0 | M18: =F13-M17 -> 0 | N18: =G13-N17 -> 0 | O18: =H13-O17 -> 0 | P18: =I13-P17 -> 0
A19: de conducere | B19: 126 | C19: 8.9 | K19: 13.63 | L19: 13.88 | M19: 12.38 | N19: 11.96 | O19: 13.63 | P19: 13.25
A20: de execuție | B20: 145 | C20: 8.10
A21: funcții complexe, inclusiv | B21: 104 | C21: 8.11
A22: de conducere | B22: 126 | C22: 8.12
A23: de execuție | B23: 145 | C23: 8.13
A24: muncitori | B24: 177 | C24: 8.14
A25: Personal angajat în total, inclusiv | B25: 100 | C25: 8.15 | D25: =D26+D30+D33 -> 0 | E25: =E26+E30+E33 -> 0 | F25: x | G25: =G26+G30+G33 -> 0 | H25: =H26+H30+H33 -> 0 | I25: =I26+I30+I33 -> 0 | K25: Aprobat la inceputul anului | L25: Aprobat la sfirsitul anului | M25: Numarul mediu prevazut pe an | N25: Numarul mediu realizat la 01.01.2020 | O25: Real incadrat la începutul anului | P25: Real incadratla sfîrsitul perioadei
A26: funcții didactice, inclusiv | B26: 105 | C26: 8.16 | F26: x | J26: cond. | K26: =D27+D31+D34 -> 0 | L26: =E27+E31+E34 -> 0 | M26: =F27+F31+F34 -> #VALUE! | N26: =G27+G31+G34 -> 0 | O26: =H27+H31+H34 -> 0 | P26: =I27+I31+I34 -> 0
A27: de conducere | B27: 120 | C27: 8.17 | F27: x | J27: exec | K27: =D28+D32+D35 -> 0 | L27: =E28+E32+E35 -> 0 | M27: =F28+F32+F35 -> #VALUE! | N27: =G28+G32+G35 -> 0 | O27: =H28+H32+H35 -> 0 | P27: =I28+I32+I35 -> 0
A28: de execuție, din care | B28: 140 | C28: 8.18 | F28: x | J28: muncitori | K28: =D36 -> 0 | L28: =E36 -> 0 | M28: =F36 -> x | N28: =G36 -> 0 | O28: =H36 -> 0 | P28: =I36 -> 0
A29: cadre didactice de sprijin | B29: 147 | C29: 8.19 | F29: x | J29: Total | K29: =K26+K27+K28 -> 0 | L29: =L26+L27+L28 -> 0 | M29: =M26+M27+M28 -> #VALUE! | N29: =N26+N27+N28 -> 0 | O29: =O26+O27+O28 -> 0 | P29: =P26+P27+P28 -> 0
A30: funcții de specialitate, inclusiv | B30: 106 | C30: 8.20 | F30: x | J30: control | K30: =K29-D25 -> 0 | L30: =L29-E25 -> 0 | M30: =M29-F25 -> #VALUE! | N30: =N29-G25 -> 0 | O30: =O29-H25 -> 0 | P30: =P29-I25 -> 0
A31: de conducere | B31: 120 | C31: 8.21 | F31: x
A32: de execuție | B32: 140 | C32: 8.22 | F32: x
A33: funcții complexe, inclusiv | B33: 107 | C33: 8.23 | F33: x
A34: de conducere | B34: 120 | C34: 8.24 | F34: x
A35: de execuție | B35: 140 | C35: 8.25 | F35: x
A36: muncitori | B36: 175 | C36: 8.26 | F36: x
A37: Numărul personalului didactic beneficiar de compensații anuale, inclusiv | B37: 108 | C37: 8.27 | D37: =D38+D39 -> 5 | E37: =E38+E39 -> 5 | F37: x | G37: x | H37: =H38+H39 -> 5 | I37: =I38+I39 -> 5
A38: cu funcție de conducere | B38: 120 | C38: 8.28 | D38: 1 | E38: 1 | F38: x | G38: x | H38: =D38 -> 1 | I38: 1
A39: cu funcție de execuție | B39: 140 | C39: 8.29 | D39: 4 | E39: 4 | F39: x | G39: x | H39: =D39 -> 4 | I39: 4
A40: Retibuirea muncii în total, inclusiv | B40: 500 | C40: 8.30 | D40: x | E40: x | H40: x | I40: x
A41: funcții didactice, inclusiv | B41: 501 | C41: 8.31 | D41: x | E41: x | H41: x | I41: x
...

Sheet scprim.21
H2: sc prim 21
A3: Aprobat prin ordinul Ministrului
A4: al Finanţelor al Republicii Moldova
A5: nr.___________al___________
A6: Retea, state si contingente ale instituriilor
A7: în perioada Tr.2 -2024 | J7: FD-048-BL
A8: Denumirea indicatorului | B8: codificatorul formularului | C8: Codul rindului | D8: Aprobat la inceputul anului | E8: Aprobat la sfirsitul anului | F8: Numarul mediu prevazut pe an | G8: Numarul mediu realizat la 30.09.2025 | H8: Real incadrat la începutul anului | I8: Real incadrat la sfîrsitul perioadei | J8: 09881 | K8: 0912 | L8: 8803 | M8: 00492 | N8: 0300
A9: 1 | B9: 2 | C9: 3 | D9: 4 | E9: 5 | F9: 6 | G9: 7 | H9: 8 | I9: 9
A10: RAPORT nr. 3-8 privind învățămîntul primar, gimnazial și liceal | C10: 8
A11: Instituții în total, inclusiv | B11: 1 | C11: 8.1 | F11: x | G11: x
A12: filiale | B12: 10 | C12: 8.2 | F12: x | G12: x
A13: Unități în state (posturi) în total, inclusiv | B13: 101 | C13: 8.3 | K13: Aprobat la inceputul anului | L13: Aprobat la sfirsitul anului | M13: Numarul mediu prevazut pe an | N13: Numarul mediu realizat la 01.01.2020 | O13: Real incadrat la începutul anului | P13: Real incadratla sfîrsitul perioadei
A14: funcții didactice, inclusiv | B14: 102 | C14: 8.4 | J14: cond. | K14: =D15+D19+D22 -> 0 | L14: =E15+E19+E22 -> 0 | M14: =F15+F19+F22 -> 0 | N14: =G15+G19+G22 -> 0 | O14: =H15+H19+H22 -> 0 | P14: =I15+I19+I22 -> 0
A15: de conducere | B15: 126 | C15: 8.5 | J15: exec | K15: =D16+D20+D23 -> 0 | L15: =E16+E20+E23 -> 0 | M15: =F16+F20+F23 -> 0 | N15: =G16+G20+G23 -> 0 | O15: =H16+H20+H23 -> 0 | P15: =I16+I20+I23 -> 0
A16: de execuție din care | B16: 145 | C16: 8.6 | J16: muncitori | K16: =D24 -> 0 | L16: =E24 -> 0 | M16: =F24 -> 0 | N16: =G24 -> 0 | O16: =H24 -> 0 | P16: =I24 -> 0
A17: cadre didactice de sprijin | B17: 146 | C17: 8.7 | J17: Total | K17: =K14+K15+K16 -> 0 | L17: =L14+L15+L16 -> 0 | M17: =M14+M15+M16 -> 0 | N17: =N14+N15+N16 -> 0 | O17: =O14+O15+O16 -> 0 | P17: =P14+P15+P16 -> 0
A18: funcții de specialitate, inclusiv | B18: 103 | C18: 8.8 | J18: control | K18: =D13-K17 -> 0 | L18: =E13-L17 -> 0 | M18: =F13-M17 -> 0 | N18: =G13-N17 -> 0 | O18: =H13-O17 -> 0 | P18: =I13-P17 -> 0
A19: de conducere | B19: 126 | C19: 8.9 | K19: 53.86 | L19: 55.92 | M19: 55.42 | N19: 54.54 | O19: 53.86 | P19: 56.14
A20: de execuție | B20: 145 | C20: 8.10
A21: funcții complexe, inclusiv | B21: 104 | C21: 8.11
A22: de conducere | B22: 126 | C22: 8.12
A23: de execuție | B23: 145 | C23: 8.13
A24: muncitori | B24: 177 | C24: 8.14
A25: Personal angajat în total, inclusiv | B25: 100 | C25: 8.15 | D25: =D26+D30+D33 -> 0 | E25: =E26+E30+E33 -> 0 | F25: x | G25: =G26+G30+G33 -> 0 | H25: =H26+H30+H33 -> 0 | I25: =I26+I30+I33 -> 0 | K25: Aprobat la inceputul anului | L25: Aprobat la sfirsitul anului | M25: Numarul mediu prevazut pe an | N25: Numarul mediu realizat la 01.01.2020 | O25: Real incadrat la începutul anului | P25: Real incadratla sfîrsitul perioadei
A26: funcții didactice, inclusiv | B26: 105 | C26: 8.16 | F26: x | J26: cond. | K26: =D27+D31+D34 -> 0 | L26: =E27+E31+E34 -> 0 | M26: =F27+F31+F34 -> #VALUE! | N26: =G27+G31+G34 -> 0 | O26: =H27+H31+H34 -> 0 | P26: =I27+I31+I34 -> 0
A27: de conducere | B27: 120 | C27: 8.17 | F27: x | J27: exec | K27: =D28+D32+D35 -> 0 | L27: =E28+E32+E35 -> 0 | M27: =F28+F32+F35 -> #VALUE! | N27: =G28+G32+G35 -> 0 | O27: =H28+H32+H35 -> 0 | P27: =I28+I32+I35 -> 0
A28: de execuție, din care | B28: 140 | C28: 8.18 | F28: x | J28: muncitori | K28: =D36 -> 0 | L28: =E36 -> 0 | M28: =F36 -> x | N28: =G36 -> 0 | O28: =H36 -> 0 | P28: =I36 -> 0
A29: cadre didactice de sprijin | B29: 147 | C29: 8.19 | F29: x | J29: Total | K29: =K26+K27+K28 -> 0 | L29: =L26+L27+L28 -> 0 | M29: =M26+M27+M28 -> #VALUE! | N29: =N26+N27+N28 -> 0 | O29: =O26+O27+O28 -> 0 | P29: =P26+P27+P28 -> 0
A30: funcții de specialitate, inclusiv | B30: 106 | C30: 8.20 | F30: x | J30: control | K30: =K29-D25 -> 0 | L30: =L29-E25 -> 0 | M30: =M29-F25 -> #VALUE! | N30: =N29-G25 -> 0 | O30: =O29-H25 -> 0 | P30: =P29-I25 -> 0
A31: de conducere | B31: 120 | C31: 8.21 | F31: x | K31: 48 | L31: 51 | M31: X | N31: 47 | O31: 48 | P31: 51
A32: de execuție | B32: 140 | C32: 8.22 | F32: x
A33: funcții complexe, inclusiv | B33: 107 | C33: 8.23 | F33: x
A34: de conducere | B34: 120 | C34: 8.24 | F34: x
A35: de execuție | B35: 140 | C35: 8.25 | F35: x
A36: muncitori | B36: 175 | C36: 8.26 | F36: x
A37: Numărul personalului didactic beneficiar de compensații anuale, inclusiv | B37: 108 | C37: 8.27 | D37: =D38+D39 -> 36 | E37: =E38+E39 -> 38 | F37: x | G37: x | H37: =H38+H39 -> 36 | I37: =I38+I39 -> 38
A38: cu funcție de conducere | B38: 120 | C38: 8.28 | D38: 4 | E38: 4 | F38: x | G38: x | H38: =D38 -> 4 | I38: 4
A39: cu funcție de execuție | B39: 140 | C39: 8.29 | D39: 32 | E39: 34 | F39: x | G39: x | H39: =D39 -> 32 | I39: 34
A40: Retibuirea muncii în total, inclusiv | B40: 500 | C40: 8.30 | D40: x | E40: x | H40: x | I40: x
A41: funcții didactice, inclusiv | B41: 501 | C41: 8.31 | D41: x | E41: x | H41: x | I41: x
...

Sheet total gimnazii
I1: total gimnazii
A3: Aprobat prin ordinul Ministrului
A4: al Finanţelor al Republicii Moldova
A5: nr.___________al___________
A6: Retea, state si contingente ale instituriilor
A7: în perioada Tr.2 -2024 | J7: FD-048-BL
A8: Denumirea indicatorului | B8: codificatorul formularului | C8: Codul rindului | D8: Aprobat la inceputul anului | E8: Aprobat la sfirsitul anului | F8: Numarul mediu prevazut pe an | G8: Numarul mediu realizat la 30.09.2025 | H8: Real incadrat la începutul anului | I8: Real incadrat la sfîrsitul perioadei | M8: 00492
A9: 1 | B9: 2 | C9: 3 | D9: 4 | E9: 5 | F9: 6 | G9: 7 | H9: 8 | I9: 9
A10: RAPORT nr. 3-8 privind învățămîntul primar, gimnazial și liceal | C10: 8
A11: Instituții în total, inclusiv | B11: 1 | C11: 8.1 | F11: x | G11: x
A12: filiale | B12: 10 | C12: 8.2 | F12: x | G12: x
A13: Unități în state (posturi) în total, inclusiv | B13: 101 | C13: 8.3 | K13: Aprobat la inceputul anului | L13: Aprobat la sfirsitul anului | M13: Numarul mediu prevazut pe an | N13: Numarul mediu realizat la 01.01.2020 | O13: Real incadrat la începutul anului | P13: Real incadratla sfîrsitul perioadei
A14: funcții didactice, inclusiv | B14: 102 | C14: 8.4 | J14: cond. | K14: =D15+D19+D22 -> 0 | L14: =E15+E19+E22 -> 0 | M14: =F15+F19+F22 -> 0 | N14: =G15+G19+G22 -> 0 | O14: =H15+H19+H22 -> 0 | P14: =I15+I19+I22 -> 0
A15: de conducere | B15: 126 | C15: 8.5 | J15: exec | K15: =D16+D20+D23 -> 0 | L15: =E16+E20+E23 -> 0 | M15: =F16+F20+F23 -> 0 | N15: =G16+G20+G23 -> 0 | O15: =H16+H20+H23 -> 0 | P15: =I16+I20+I23 -> 0
A16: de execuție din care | B16: 145 | C16: 8.6 | J16: muncitori | K16: =D24 -> 0 | L16: =E24 -> 0 | M16: =F24 -> 0 | N16: =G24 -> 0 | O16: =H24 -> 0 | P16: =I24 -> 0
A17: cadre didactice de sprijin | B17: 146 | C17: 8.7 | J17: Total | K17: =K14+K15+K16 -> 0 | L17: =L14+L15+L16 -> 0 | M17: =M14+M15+M16 -> 0 | N17: =N14+N15+N16 -> 0 | O17: =O14+O15+O16 -> 0 | P17: =P14+P15+P16 -> 0
A18: funcții de specialitate, inclusiv | B18: 103 | C18: 8.8 | J18: control | K18: =D13-K17 -> 0 | L18: =E13-L17 -> 0 | M18: =F13-M17 -> 0 | N18: =G13-N17 -> 0 | O18: =H13-O17 -> 0 | P18: =I13-P17 -> 0
A19: de conducere | B19: 126 | C19: 8.9 | K19: 351.7 | L19: 363.46 | M19: 358.96 | N19: 338.49 | O19: 351.7 | P19: 337.89
A20: de execuție | B20: 145 | C20: 8.10 | K20: =K17-K19 -> -351.7 | L20: =L17-L19 -> -363.46 | M20: =M17-M19 -> -358.96 | N20: =N17-N19 -> -338.49 | O20: =O17-O19 -> -351.7 | P20: =P17-P19 -> -337.89
A21: funcții complexe, inclusiv | B21: 104 | C21: 8.11
A22: de conducere | B22: 126 | C22: 8.12
A23: de execuție | B23: 145 | C23: 8.13
A24: muncitori | B24: 177 | C24: 8.14
A25: Personal angajat în total, inclusiv | B25: 100 | C25: 8.15 | D25: =D26+D30+D33 -> 0 | E25: =E26+E30+E33 -> 0 | F25: x | G25: =G26+G30+G33 -> 0 | H25: =H26+H30+H33 -> 0 | I25: =I26+I30+I33 -> 0 | K25: Aprobat la inceputul anului | L25: Aprobat la sfirsitul anului | M25: Numarul mediu prevazut pe an | N25: Numarul mediu realizat la 01.01.2020 | O25: Real incadrat la începutul anului | P25: Real incadratla sfîrsitul perioadei
A26: funcții didactice, inclusiv | B26: 105 | C26: 8.16 | F26: x | J26: cond. | K26: =D27+D31+D34 -> 0 | L26: =E27+E31+E34 -> 0 | M26: =F27+F31+F34 -> #VALUE! | N26: =G27+G31+G34 -> 0 | O26: =H27+H31+H34 -> 0 | P26: =I27+I31+I34 -> 0
A27: de conducere | B27: 120 | C27: 8.17 | F27: x | J27: exec | K27: =D28+D32+D35 -> 0 | L27: =E28+E32+E35 -> 0 | M27: =F28+F32+F35 -> #VALUE! | N27: =G28+G32+G35 -> 0 | O27: =H28+H32+H35 -> 0 | P27: =I28+I32+I35 -> 0
A28: de execuție, din care | B28: 140 | C28: 8.18 | F28: x | J28: muncitori | K28: =D36 -> 0 | L28: =E36 -> 0 | M28: =F36 -> x | N28: =G36 -> 0 | O28: =H36 -> 0 | P28: =I36 -> 0
A29: cadre didactice de sprijin | B29: 147 | C29: 8.19 | F29: x | J29: Total | K29: =K26+K27+K28 -> 0 | L29: =L26+L27+L28 -> 0 | M29: =M26+M27+M28 -> #VALUE! | N29: =N26+N27+N28 -> 0 | O29: =O26+O27+O28 -> 0 | P29: =P26+P27+P28 -> 0
A30: funcții de specialitate, inclusiv | B30: 106 | C30: 8.20 | F30: x | J30: control | K30: =K29-D25 -> 0 | L30: =L29-E25 -> 0 | M30: =M29-F25 -> #VALUE! | N30: =N29-G25 -> 0 | O30: =O29-H25 -> 0 | P30: =P29-I25 -> 0
A31: de conducere | B31: 120 | C31: 8.21 | F31: x | K31: 341 | L31: 341 | M31: X | N31: 318 | O31: 341 | P31: 335
A32: de execuție | B32: 140 | C32: 8.22 | F32: x | K32: =K29-K31 -> -341 | L32: =L29-L31 -> -341 | M32: =M29-M31 -> #VALUE! | N32: =N29-N31 -> -318 | O32: =O29-O31 -> -341 | P32: =P29-P31 -> -335
A33: funcții complexe, inclusiv | B33: 107 | C33: 8.23 | F33: x
A34: de conducere | B34: 120 | C34: 8.24 | F34: x
A35: de execuție | B35: 140 | C35: 8.25 | F35: x
A36: muncitori | B36: 175 | C36: 8.26 | F36: x
A37: Numărul personalului didactic beneficiar de compensații anuale, inclusiv | B37: 108 | C37: 8.27 | D37: =D38+D39 -> 155 | E37: =E38+E39 -> 166 | F37: x | G37: x | H37: =H38+H39 -> 155 | I37: =I38+I39 -> 160 | J37: =J38+J39 -> 154 | K37: =J37-I37 -> -6
A38: cu funcție de conducere | B38: 120 | C38: 8.28 | D38: ='gim 2'!D38+'gim 3'!D38+'gim 6'!D38+'gim 7'!D38+'gim 9'!D38+'gim 10'!D38+'gim 14'!D38+'gim 19'!D38+'gim Cuza'!D38 -> 22 | E38: ='gim 2'!E38+'gim 3'!E38+'gim 6'!E38+'gim 7'!E38+'gim 9'!E38+'gim 10'!E38+'gim 14'!E38+'gim 19'!E38+'gim Cuza'!E38 -> 22 | F38: x | G38: x | H38: =D38 -> 22 | I38: ='gim 2'!I38+'gim 3'!I38+'gim 6'!I38+'gim 7'!I38+'gim 9'!I38+'gim 10'!I38+'gim 14'!I38+'gim 19'!I38+'gim Cuza'!I38 -> 22 | J38: 29 | K38: =J38-I38 -> 7
A39: cu funcție de execuție | B39: 140 | C39: 8.29 | D39: ='gim 2'!D39+'gim 3'!D39+'gim 6'!D39+'gim 7'!D39+'gim 9'!D39+'gim 10'!D39+'gim 14'!D39+'gim 19'!D39+'gim Cuza'!D39 -> 133 | E39: ='gim 2'!E39+'gim 3'!E39+'gim 6'!E39+'gim 7'!E39+'gim 9'!E39+'gim 10'!E39+'gim 14'!E39+'gim 19'!E39+'gim Cuza'!E39 -> 144 | F39: x | G39: x | H39: =D39 -> 133 | I39: ='gim 2'!I39+'gim 3'!I39+'gim 6'!I39+'gim 7'!I39+'gim 9'!I39+'gim 10'!I39+'gim 14'!I39+'gim 19'!I39+'gim Cuza'!I39 -> 138 | J39: 125 | K39: =J39-I39 -> -13
A40: Retibuirea muncii în total, inclusiv | B40: 500 | C40: 8.30 | D40: x | E40: x | F40: =F41+F45+F48 -> 0 | G40: =G41+G45+G48 -> 0 | H40: x | I40: x
A41: funcții didactice, inclusiv | B41: 501 | C41: 8.31 | D41: x | E41: x | H41: x | I41: x
...

Sheet gim 10
H2: gim 10
A3: Aprobat prin ordinul Ministrului
A4: al Finanţelor al Republicii Moldova
A5: nr.___________al___________
A6: Retea, state si contingente ale instituriilor
A7: în perioada Tr.2 -2024 | J7: FD-048-BL
A8: Denumirea indicatorului | B8: codificatorul formularului | C8: Codul rindului | D8: Aprobat la inceputul anului | E8: Aprobat la sfirsitul anului | F8: Numarul mediu prevazut pe an | G8: Numarul mediu realizat la 30.09.2025 | H8: Real incadrat la începutul anului | I8: Real incadrat la sfîrsitul perioadei | J8: 04151 | K8: 0921 | L8: 8804 | M8: 00492 | N8: 0300
A9: 1 | B9: 2 | C9: 3 | D9: 4 | E9: 5 | F9: 6 | G9: 7 | H9: 8 | I9: 9
A10: RAPORT nr. 3-8 privind învățămîntul primar, gimnazial și liceal | C10: 8
A11: Instituții în total, inclusiv | B11: 1 | C11: 8.1 | F11: x | G11: x
A12: filiale | B12: 10 | C12: 8.2 | F12: x | G12: x
A13: Unități în state (posturi) în total, inclusiv | B13: 101 | C13: 8.3 | K13: Aprobat la inceputul anului | L13: Aprobat la sfirsitul anului | M13: Numarul mediu prevazut pe an | N13: Numarul mediu realizat la 01.01.2020 | O13: Real incadrat la începutul anului | P13: Real incadratla sfîrsitul perioadei
A14: funcții didactice, inclusiv | B14: 102 | C14: 8.4 | J14: cond. | K14: =D15+D19+D22 -> 0 | L14: =E15+E19+E22 -> 0 | M14: =F15+F19+F22 -> 0 | N14: =G15+G19+G22 -> 0 | O14: =H15+H19+H22 -> 0 | P14: =I15+I19+I22 -> 0
A15: de conducere | B15: 126 | C15: 8.5 | J15: exec | K15: =D16+D20+D23 -> 0 | L15: =E16+E20+E23 -> 0 | M15: =F16+F20+F23 -> 0 | N15: =G16+G20+G23 -> 0 | O15: =H16+H20+H23 -> 0 | P15: =I16+I20+I23 -> 0
A16: de execuție din care | B16: 145 | C16: 8.6 | J16: muncitori | K16: =D24 -> 0 | L16: =E24 -> 0 | M16: =F24 -> 0 | N16: =G24 -> 0 | O16: =H24 -> 0 | P16: =I24 -> 0
A17: cadre didactice de sprijin | B17: 146 | C17: 8.7 | J17: Total | K17: =K14+K15+K16 -> 0 | L17: =L14+L15+L16 -> 0 | M17: =M14+M15+M16 -> 0 | N17: =N14+N15+N16 -> 0 | O17: =O14+O15+O16 -> 0 | P17: =P14+P15+P16 -> 0
A18: funcții de specialitate, inclusiv | B18: 103 | C18: 8.8 | J18: control | K18: =D13-K17 -> 0 | L18: =E13-L17 -> 0 | M18: =F13-M17 -> 0 | N18: =G13-N17 -> 0 | O18: =H13-O17 -> 0 | P18: =I13-P17 -> 0
A19: de conducere | B19: 126 | C19: 8.9
A20: de execuție | B20: 145 | C20: 8.10
A21: funcții complexe, inclusiv | B21: 104 | C21: 8.11
A22: de conducere | B22: 126 | C22: 8.12
A23: de execuție | B23: 145 | C23: 8.13
A24: muncitori | B24: 177 | C24: 8.14
A25: Personal angajat în total, inclusiv | B25: 100 | C25: 8.15 | D25: =D26+D30+D33 -> 0 | E25: =E26+E30+E33 -> 0 | F25: x | G25: =G26+G30+G33 -> 0 | H25: =H26+H30+H33 -> 0 | I25: =I26+I30+I33 -> 0 | K25: Aprobat la inceputul anului | L25: Aprobat la sfirsitul anului | M25: Numarul mediu prevazut pe an | N25: Numarul mediu realizat la 01.01.2020 | O25: Real incadrat la începutul anului | P25: Real incadratla sfîrsitul perioadei
A26: funcții didactice, inclusiv | B26: 105 | C26: 8.16 | F26: x | J26: cond. | K26: =D27+D31+D34 -> 0 | L26: =E27+E31+E34 -> 0 | M26: =F27+F31+F34 -> #VALUE! | N26: =G27+G31+G34 -> 0 | O26: =H27+H31+H34 -> 0 | P26: =I27+I31+I34 -> 0
A27: de conducere | B27: 120 | C27: 8.17 | F27: x | J27: exec | K27: =D28+D32+D35 -> 0 | L27: =E28+E32+E35 -> 0 | M27: =F28+F32+F35 -> #VALUE! | N27: =G28+G32+G35 -> 0 | O27: =H28+H32+H35 -> 0 | P27: =I28+I32+I35 -> 0
A28: de execuție, din care | B28: 140 | C28: 8.18 | F28: x | J28: muncitori | K28: =D36 -> 0 | L28: =E36 -> 0 | M28: =F36 -> x | N28: =G36 -> 0 | O28: =H36 -> 0 | P28: =I36 -> 0
A29: cadre didactice de sprijin | B29: 147 | C29: 8.19 | F29: x | J29: Total | K29: =K26+K27+K28 -> 0 | L29: =L26+L27+L28 -> 0 | M29: =M26+M27+M28 -> #VALUE! | N29: =N26+N27+N28 -> 0 | O29: =O26+O27+O28 -> 0 | P29: =P26+P27+P28 -> 0
A30: funcții de specialitate, inclusiv | B30: 106 | C30: 8.20 | F30: x | J30: control | K30: =K29-D25 -> 0 | L30: =L29-E25 -> 0 | M30: =M29-F25 -> #VALUE! | N30: =N29-G25 -> 0 | O30: =O29-H25 -> 0 | P30: =P29-I25 -> 0
A31: de conducere | B31: 120 | C31: 8.21 | F31: x
A32: de execuție | B32: 140 | C32: 8.22 | F32: x
A33: funcții complexe, inclusiv | B33: 107 | C33: 8.23 | F33: x
A34: de conducere | B34: 120 | C34: 8.24 | F34: x
A35: de execuție | B35: 140 | C35: 8.25 | F35: x
A36: muncitori | B36: 175 | C36: 8.26 | F36: x
A37: Numărul personalului didactic beneficiar de compensații anuale, inclusiv | B37: 108 | C37: 8.27 | D37: =D38+D39 -> 16 | E37: =E38+E39 -> 16 | F37: x | G37: x | H37: =H38+H39 -> 16 | I37: =I38+I39 -> 16
A38: cu funcție de conducere | B38: 120 | C38: 8.28 | D38: 2 | E38: 2 | F38: x | G38: x | H38: =D38 -> 2 | I38: 2
A39: cu funcție de execuție | B39: 140 | C39: 8.29 | D39: 14 | E39: 14 | F39: x | G39: x | H39: =D39 -> 14 | I39: 14
A40: Retibuirea muncii în total, inclusiv | B40: 500 | C40: 8.30 | D40: x | E40: x | F40: =F41+F45+F48 -> 0 | G40: =G41+G45+G48 -> 0 | H40: x | I40: x
A41: funcții didactice, inclusiv | B41: 501 | C41: 8.31 | D41: x | E41: x | H41: x | I41: x
...

Sheet gim 2
H2: gim 2
A3: Aprobat prin ordinul Ministrului
A4: al Finanţelor al Republicii Moldova
A5: nr.___________al___________
A6: Retea, state si contingente ale instituriilor
A7: în perioada Tr.2 -2024 | J7: FD-048-BL
A8: Denumirea indicatorului | B8: codificatorul formularului | C8: Codul rindului | D8: Aprobat la inceputul anului | E8: Aprobat la sfirsitul anului | F8: Numarul mediu prevazut pe an | G8: Numarul mediu realizat la 30.09.2025 | H8: Real incadrat la începutul anului | I8: Real incadrat la sfîrsitul perioadei | J8: 09864 | K8: 0921 | L8: 8804 | M8: 00492 | N8: 0300
A9: 1 | B9: 2 | C9: 3 | D9: 4 | E9: 5 | F9: 6 | G9: 7 | H9: 8 | I9: 9
A10: RAPORT nr. 3-8 privind învățămîntul primar, gimnazial și liceal | C10: 8
A11: Instituții în total, inclusiv | B11: 1 | C11: 8.1 | F11: x | G11: x
A12: filiale | B12: 10 | C12: 8.2 | F12: x | G12: x
A13: Unități în state (posturi) în total, inclusiv | B13: 101 | C13: 8.3 | K13: Aprobat la inceputul anului | L13: Aprobat la sfirsitul anului | M13: Numarul mediu prevazut pe an | N13: Numarul mediu realizat la 01.01.2020 | O13: Real incadrat la începutul anului | P13: Real incadratla sfîrsitul perioadei
A14: funcții didactice, inclusiv | B14: 102 | C14: 8.4 | J14: cond. | K14: =D15+D19+D22 -> 0 | L14: =E15+E19+E22 -> 0 | M14: =F15+F19+F22 -> 0 | N14: =G15+G19+G22 -> 0 | O14: =H15+H19+H22 -> 0 | P14: =I15+I19+I22 -> 0
A15: de conducere | B15: 126 | C15: 8.5 | J15: exec | K15: =D16+D20+D23 -> 0 | L15: =E16+E20+E23 -> 0 | M15: =F16+F20+F23 -> 0 | N15: =G16+G20+G23 -> 0 | O15: =H16+H20+H23 -> 0 | P15: =I16+I20+I23 -> 0
A16: de execuție din care | B16: 145 | C16: 8.6 | J16: muncitori | K16: =D24 -> 0 | L16: =E24 -> 0 | M16: =F24 -> 0 | N16: =G24 -> 0 | O16: =H24 -> 0 | P16: =I24 -> 0
A17: cadre didactice de sprijin | B17: 146 | C17: 8.7 | J17: Total | K17: =K14+K15+K16 -> 0 | L17: =L14+L15+L16 -> 0 | M17: =M14+M15+M16 -> 0 | N17: =N14+N15+N16 -> 0 | O17: =O14+O15+O16 -> 0 | P17: =P14+P15+P16 -> 0
A18: funcții de specialitate, inclusiv | B18: 103 | C18: 8.8 | J18: control | K18: =D13-K17 -> 0 | L18: =E13-L17 -> 0 | M18: =F13-M17 -> 0 | N18: =G13-N17 -> 0 | O18: =H13-O17 -> 0 | P18: =I13-P17 -> 0
A19: de conducere | B19: 126 | C19: 8.9
A20: de execuție | B20: 145 | C20: 8.10
A21: funcții complexe, inclusiv | B21: 104 | C21: 8.11
A22: de conducere | B22: 126 | C22: 8.12
A23: de execuție | B23: 145 | C23: 8.13
A24: muncitori | B24: 177 | C24: 8.14
A25: Personal angajat în total, inclusiv | B25: 100 | C25: 8.15 | D25: =D26+D30+D33 -> 0 | E25: =E26+E30+E33 -> 0 | F25: x | G25: =G26+G30+G33 -> 0 | H25: =H26+H30+H33 -> 0 | I25: =I26+I30+I33 -> 0 | K25: Aprobat la inceputul anului | L25: Aprobat la sfirsitul anului | M25: Numarul mediu prevazut pe an | N25: Numarul mediu realizat la 01.01.2020 | O25: Real incadrat la începutul anului | P25: Real incadratla sfîrsitul perioadei
A26: funcții didactice, inclusiv | B26: 105 | C26: 8.16 | F26: x | J26: cond. | K26: =D27+D31+D34 -> 0 | L26: =E27+E31+E34 -> 0 | M26: =F27+F31+F34 -> #VALUE! | N26: =G27+G31+G34 -> 0 | O26: =H27+H31+H34 -> 0 | P26: =I27+I31+I34 -> 0
A27: de conducere | B27: 120 | C27: 8.17 | F27: x | J27: exec | K27: =D28+D32+D35 -> 0 | L27: =E28+E32+E35 -> 0 | M27: =F28+F32+F35 -> #VALUE! | N27: =G28+G32+G35 -> 0 | O27: =H28+H32+H35 -> 0 | P27: =I28+I32+I35 -> 0
A28: de execuție, din care | B28: 140 | C28: 8.18 | F28: x | J28: muncitori | K28: =D36 -> 0 | L28: =E36 -> 0 | M28: =F36 -> x | N28: =G36 -> 0 | O28: =H36 -> 0 | P28: =I36 -> 0
A29: cadre didactice de sprijin | B29: 147 | C29: 8.19 | F29: x | J29: Total | K29: =K26+K27+K28 -> 0 | L29: =L26+L27+L28 -> 0 | M29: =M26+M27+M28 -> #VALUE! | N29: =N26+N27+N28 -> 0 | O29: =O26+O27+O28 -> 0 | P29: =P26+P27+P28 -> 0
A30: funcții de specialitate, inclusiv | B30: 106 | C30: 8.20 | F30: x | J30: control | K30: =K29-D25 -> 0 | L30: =L29-E25 -> 0 | M30: =M29-F25 -> #VALUE! | N30: =N29-G25 -> 0 | O30: =O29-H25 -> 0 | P30: =P29-I25 -> 0
A31: de conducere | B31: 120 | C31: 8.21 | F31: x
A32: de execuție | B32: 140 | C32: 8.22 | F32: x
A33: funcții complexe, inclusiv | B33: 107 | C33: 8.23 | F33: x
A34: de conducere | B34: 120 | C34: 8.24 | F34: x
A35: de execuție | B35: 140 | C35: 8.25 | F35: x
A36: muncitori | B36: 175 | C36: 8.26 | F36: x
A37: Numărul personalului didactic beneficiar de compensații anuale, inclusiv | B37: 108 | C37: 8.27 | D37: =D38+D39 -> 15 | E37: =E38+E39 -> 17 | F37: x | G37: x | H37: =H38+H39 -> 15 | I37: =I38+I39 -> 14
A38: cu funcție de conducere | B38: 120 | C38: 8.28 | D38: 3 | E38: 3 | F38: x | G38: x | H38: =D38 -> 3 | I38: 3
A39: cu funcție de execuție | B39: 140 | C39: 8.29 | D39: 12 | E39: 14 | F39: x | G39: x | H39: =D39 -> 12 | I39: 11
A40: Retibuirea muncii în total, inclusiv | B40: 500 | C40: 8.30 | D40: x | E40: x | H40: x | I40: x
A41: funcții didactice, inclusiv | B41: 501 | C41: 8.31 | D41: x | E41: x | H41: x | I41: x
...

Sheet gim 3
H2: gim 3
A3: Aprobat prin ordinul Ministrului
A4: al Finanţelor al Republicii Moldova
A5: nr.___________al___________
A6: Retea, state si contingente ale instituriilor
A7: în perioada Tr.2 -2024 | J7: FD-048-BL
A8: Denumirea indicatorului | B8: codificatorul formularului | C8: Codul rindului | D8: Aprobat la inceputul anului | E8: Aprobat la sfirsitul anului | F8: Numarul mediu prevazut pe an | G8: Numarul mediu realizat la 30.09.2025 | H8: Real incadrat la începutul anului | I8: Real incadrat la sfîrsitul perioadei | J8: 09865 | K8: 0921 | L8: 8804 | M8: 00492 | N8: 0300
A9: 1 | B9: 2 | C9: 3 | D9: 4 | E9: 5 | F9: 6 | G9: 7 | H9: 8 | I9: 9
A10: RAPORT nr. 3-8 privind învățămîntul primar, gimnazial și liceal | C10: 8
A11: Instituții în total, inclusiv | B11: 1 | C11: 8.1 | F11: x | G11: x
A12: filiale | B12: 10 | C12: 8.2 | F12: x | G12: x
A13: Unități în state (posturi) în total, inclusiv | B13: 101 | C13: 8.3 | K13: Aprobat la inceputul anului | L13: Aprobat la sfirsitul anului | M13: Numarul mediu prevazut pe an | N13: Numarul mediu realizat la 01.01.2020 | O13: Real incadrat la începutul anului | P13: Real incadratla sfîrsitul perioadei
A14: funcții didactice, inclusiv | B14: 102 | C14: 8.4 | J14: cond. | K14: =D15+D19+D22 -> 0 | L14: =E15+E19+E22 -> 0 | M14: =F15+F19+F22 -> 0 | N14: =G15+G19+G22 -> 0 | O14: =H15+H19+H22 -> 0 | P14: =I15+I19+I22 -> 0
A15: de conducere | B15: 126 | C15: 8.5 | J15: exec | K15: =D16+D20+D23 -> 0 | L15: =E16+E20+E23 -> 0 | M15: =F16+F20+F23 -> 0 | N15: =G16+G20+G23 -> 0 | O15: =H16+H20+H23 -> 0 | P15: =I16+I20+I23 -> 0
A16: de execuție din care | B16: 145 | C16: 8.6 | J16: muncitori | K16: =D24 -> 0 | L16: =E24 -> 0 | M16: =F24 -> 0 | N16: =G24 -> 0 | O16: =H24 -> 0 | P16: =I24 -> 0
A17: cadre didactice de sprijin | B17: 146 | C17: 8.7 | J17: Total | K17: =K14+K15+K16 -> 0 | L17: =L14+L15+L16 -> 0 | M17: =M14+M15+M16 -> 0 | N17: =N14+N15+N16 -> 0 | O17: =O14+O15+O16 -> 0 | P17: =P14+P15+P16 -> 0
A18: funcții de specialitate, inclusiv | B18: 103 | C18: 8.8 | J18: control | K18: =D13-K17 -> 0 | L18: =E13-L17 -> 0 | M18: =F13-M17 -> 0 | N18: =G13-N17 -> 0 | O18: =H13-O17 -> 0 | P18: =I13-P17 -> 0
A19: de conducere | B19: 126 | C19: 8.9
A20: de execuție | B20: 145 | C20: 8.10
A21: funcții complexe, inclusiv | B21: 104 | C21: 8.11
A22: de conducere | B22: 126 | C22: 8.12
A23: de execuție | B23: 145 | C23: 8.13
A24: muncitori | B24: 177 | C24: 8.14
A25: Personal angajat în total, inclusiv | B25: 100 | C25: 8.15 | D25: =D26+D30+D33 -> 0 | E25: =E26+E30+E33 -> 0 | F25: x | G25: =G26+G30+G33 -> 0 | H25: =H26+H30+H33 -> 0 | I25: =I26+I30+I33 -> 0 | K25: Aprobat la inceputul anului | L25: Aprobat la sfirsitul anului | M25: Numarul mediu prevazut pe an | N25: Numarul mediu realizat la 01.01.2020 | O25: Real incadrat la începutul anului | P25: Real incadratla sfîrsitul perioadei
A26: funcții didactice, inclusiv | B26: 105 | C26: 8.16 | F26: x | J26: cond. | K26: =D27+D31+D34 -> 0 | L26: =E27+E31+E34 -> 0 | M26: =F27+F31+F34 -> #VALUE! | N26: =G27+G31+G34 -> 0 | O26: =H27+H31+H34 -> 0 | P26: =I27+I31+I34 -> 0
A27: de conducere | B27: 120 | C27: 8.17 | F27: x | J27: exec | K27: =D28+D32+D35 -> 0 | L27: =E28+E32+E35 -> 0 | M27: =F28+F32+F35 -> #VALUE! | N27: =G28+G32+G35 -> 0 | O27: =H28+H32+H35 -> 0 | P27: =I28+I32+I35 -> 0
A28: de execuție, din care | B28: 140 | C28: 8.18 | F28: x | J28: muncitori | K28: =D36 -> 0 | L28: =E36 -> 0 | M28: =F36 -> x | N28: =G36 -> 0 | O28: =H36 -> 0 | P28: =I36 -> 0
A29: cadre didactice de sprijin | B29: 147 | C29: 8.19 | F29: x | J29: Total | K29: =K26+K27+K28 -> 0 | L29: =L26+L27+L28 -> 0 | M29: =M26+M27+M28 -> #VALUE! | N29: =N26+N27+N28 -> 0 | O29: =O26+O27+O28 -> 0 | P29: =P26+P27+P28 -> 0
A30: funcții de specialitate, inclusiv | B30: 106 | C30: 8.20 | F30: x | J30: control | K30: =K29-D25 -> 0 | L30: =L29-E25 -> 0 | M30: =M29-F25 -> #VALUE! | N30: =N29-G25 -> 0 | O30: =O29-H25 -> 0 | P30: =P29-I25 -> 0
A31: de conducere | B31: 120 | C31: 8.21 | F31: x
A32: de execuție | B32: 140 | C32: 8.22 | F32: x
A33: funcții complexe, inclusiv | B33: 107 | C33: 8.23 | F33: x
A34: de conducere | B34: 120 | C34: 8.24 | F34: x
A35: de execuție | B35: 140 | C35: 8.25 | F35: x
A36: muncitori | B36: 175 | C36: 8.26 | F36: x
A37: Numărul personalului didactic beneficiar de compensații anuale, inclusiv | B37: 108 | C37: 8.27 | D37: =D38+D39 -> 13 | E37: =E38+E39 -> 16 | F37: x | G37: x | H37: =H38+H39 -> 13 | I37: =I38+I39 -> 14
A38: cu funcție de conducere | B38: 120 | C38: 8.28 | D38: 2 | E38: 2 | F38: x | G38: x | H38: =D38 -> 2 | I38: 2
A39: cu funcție de execuție | B39: 140 | C39: 8.29 | D39: 11 | E39: 14 | F39: x | G39: x | H39: =D39 -> 11 | I39: 12
A40: Retibuirea muncii în total, inclusiv | B40: 500 | C40: 8.30 | D40: x | E40: x | H40: x | I40: x
A41: funcții didactice, inclusiv | B41: 501 | C41: 8.31 | D41: x | E41: x | H41: x | I41: x
...

Sheet gim 6
H2: gim 6
A3: Aprobat prin ordinul Ministrului
A4: al Finanţelor al Republicii Moldova
A5: nr.___________al___________
A6: Retea, state si contingente ale instituriilor
A7: în perioada Tr.2 -2024 | J7: FD-048-BL
A8: Denumirea indicatorului | B8: codificatorul formularului | C8: Codul rindului | D8: Aprobat la inceputul anului | E8: Aprobat la sfirsitul anului | F8: Numarul mediu prevazut pe an | G8: Numarul mediu realizat la 30.09.2025 | H8: Real incadrat la începutul anului | I8: Real incadrat la sfîrsitul perioadei | J8: 09868 | K8: 0921 | L8: 8804 | M8: 00492 | N8: 0300
A9: 1 | B9: 2 | C9: 3 | D9: 4 | E9: 5 | F9: 6 | G9: 7 | H9: 8 | I9: 9
A10: RAPORT nr. 3-8 privind învățămîntul primar, gimnazial și liceal | C10: 8
A11: Instituții în total, inclusiv | B11: 1 | C11: 8.1 | F11: x | G11: x
A12: filiale | B12: 10 | C12: 8.2 | F12: x | G12: x
A13: Unități în state (posturi) în total, inclusiv | B13: 101 | C13: 8.3 | K13: Aprobat la inceputul anului | L13: Aprobat la sfirsitul anului | M13: Numarul mediu prevazut pe an | N13: Numarul mediu realizat la 01.01.2020 | O13: Real incadrat la începutul anului | P13: Real incadratla sfîrsitul perioadei
A14: funcții didactice, inclusiv | B14: 102 | C14: 8.4 | J14: cond. | K14: =D15+D19+D22 -> 0 | L14: =E15+E19+E22 -> 0 | M14: =F15+F19+F22 -> 0 | N14: =G15+G19+G22 -> 0 | O14: =H15+H19+H22 -> 0 | P14: =I15+I19+I22 -> 0
A15: de conducere | B15: 126 | C15: 8.5 | J15: exec | K15: =D16+D20+D23 -> 0 | L15: =E16+E20+E23 -> 0 | M15: =F16+F20+F23 -> 0 | N15: =G16+G20+G23 -> 0 | O15: =H16+H20+H23 -> 0 | P15: =I16+I20+I23 -> 0
A16: de execuție din care | B16: 145 | C16: 8.6 | J16: muncitori | K16: =D24 -> 0 | L16: =E24 -> 0 | M16: =F24 -> 0 | N16: =G24 -> 0 | O16: =H24 -> 0 | P16: =I24 -> 0
A17: cadre didactice de sprijin | B17: 146 | C17: 8.7 | J17: Total | K17: =K14+K15+K16 -> 0 | L17: =L14+L15+L16 -> 0 | M17: =M14+M15+M16 -> 0 | N17: =N14+N15+N16 -> 0 | O17: =O14+O15+O16 -> 0 | P17: =P14+P15+P16 -> 0
A18: funcții de specialitate, inclusiv | B18: 103 | C18: 8.8 | J18: control | K18: =D13-K17 -> 0 | L18: =E13-L17 -> 0 | M18: =F13-M17 -> 0 | N18: =G13-N17 -> 0 | O18: =H13-O17 -> 0 | P18: =I13-P17 -> 0
A19: de conducere | B19: 126 | C19: 8.9
A20: de execuție | B20: 145 | C20: 8.10
A21: funcții complexe, inclusiv | B21: 104 | C21: 8.11
A22: de conducere | B22: 126 | C22: 8.12
A23: de execuție | B23: 145 | C23: 8.13
A24: muncitori | B24: 177 | C24: 8.14
A25: Personal angajat în total, inclusiv | B25: 100 | C25: 8.15 | D25: =D26+D30+D33 -> 0 | E25: =E26+E30+E33 -> 0 | F25: x | G25: =G26+G30+G33 -> 0 | H25: =H26+H30+H33 -> 0 | I25: =I26+I30+I33 -> 0 | K25: Aprobat la inceputul anului | L25: Aprobat la sfirsitul anului | M25: Numarul mediu prevazut pe an | N25: Numarul mediu realizat la 01.01.2020 | O25: Real incadrat la începutul anului | P25: Real incadratla sfîrsitul perioadei
A26: funcții didactice, inclusiv | B26: 105 | C26: 8.16 | F26: x | J26: cond. | K26: =D27+D31+D34 -> 0 | L26: =E27+E31+E34 -> 0 | M26: =F27+F31+F34 -> #VALUE! | N26: =G27+G31+G34 -> 0 | O26: =H27+H31+H34 -> 0 | P26: =I27+I31+I34 -> 0
A27: de conducere | B27: 120 | C27: 8.17 | F27: x | J27: exec | K27: =D28+D32+D35 -> 0 | L27: =E28+E32+E35 -> 0 | M27: =F28+F32+F35 -> #VALUE! | N27: =G28+G32+G35 -> 0 | O27: =H28+H32+H35 -> 0 | P27: =I28+I32+I35 -> 0
A28: de execuție, din care | B28: 140 | C28: 8.18 | F28: x | J28: muncitori | K28: =D36 -> 0 | L28: =E36 -> 0 | M28: =F36 -> x | N28: =G36 -> 0 | O28: =H36 -> 0 | P28: =I36 -> 0
A29: cadre didactice de sprijin | B29: 147 | C29: 8.19 | F29: x | J29: Total | K29: =K26+K27+K28 -> 0 | L29: =L26+L27+L28 -> 0 | M29: =M26+M27+M28 -> #VALUE! | N29: =N26+N27+N28 -> 0 | O29: =O26+O27+O28 -> 0 | P29: =P26+P27+P28 -> 0
A30: funcții de specialitate, inclusiv | B30: 106 | C30: 8.20 | F30: x | J30: control | K30: =K29-D25 -> 0 | L30: =L29-E25 -> 0 | M30: =M29-F25 -> #VALUE! | N30: =N29-G25 -> 0 | O30: =O29-H25 -> 0 | P30: =P29-I25 -> 0
A31: de conducere | B31: 120 | C31: 8.21 | F31: x
A32: de execuție | B32: 140 | C32: 8.22 | F32: x
A33: funcții complexe, inclusiv | B33: 107 | C33: 8.23 | F33: x
A34: de conducere | B34: 120 | C34: 8.24 | F34: x
A35: de execuție | B35: 140 | C35: 8.25 | F35: x
A36: muncitori | B36: 175 | C36: 8.26 | F36: x
A37: Numărul personalului didactic beneficiar de compensații anuale, inclusiv | B37: 108 | C37: 8.27 | D37: =D38+D39 -> 15 | E37: =E38+E39 -> 17 | F37: x | G37: x | H37: =H38+H39 -> 15 | I37: =I38+I39 -> 17
A38: cu funcție de conducere | B38: 120 | C38: 8.28 | D38: 2 | E38: 2 | F38: x | G38: x | H38: =D38 -> 2 | I38: 2
A39: cu funcție de execuție | B39: 140 | C39: 8.29 | D39: 13 | E39: 15 | F39: x | G39: x | H39: =D39 -> 13 | I39: 15
A40: Retibuirea muncii în total, inclusiv | B40: 500 | C40: 8.30 | D40: x | E40: x | F40: =F41+F45+F48 -> 0 | G40: =G41+G45+G48 -> 0 | H40: x | I40: x
A41: funcții didactice, inclusiv | B41: 501 | C41: 8.31 | D41: x | E41: x | H41: x | I41: x
...

Sheet gim 7
H2: gim 7
A3: Aprobat prin ordinul Ministrului
A4: al Finanţelor al Republicii Moldova
A5: nr.___________al___________
A6: Retea, state si contingente ale instituriilor
A7: în perioada Tr.2 -2024 | J7: FD-048-BL
A8: Denumirea indicatorului | B8: codificatorul formularului | C8: Codul rindului | D8: Aprobat la inceputul anului | E8: Aprobat la sfirsitul anului | F8: Numarul mediu prevazut pe an | G8: Numarul mediu realizat la 30.09.2025 | H8: Real incadrat la începutul anului | I8: Real incadrat la sfîrsitul perioadei | J8: 09869 | K8: 0921 | L8: 8804 | M8: 00492 | N8: 0300
A9: 1 | B9: 2 | C9: 3 | D9: 4 | E9: 5 | F9: 6 | G9: 7 | H9: 8 | I9: 9
A10: RAPORT nr. 3-8 privind învățămîntul primar, gimnazial și liceal | C10: 8
A11: Instituții în total, inclusiv | B11: 1 | C11: 8.1 | F11: x | G11: x
A12: filiale | B12: 10 | C12: 8.2 | F12: x | G12: x
A13: Unități în state (posturi) în total, inclusiv | B13: 101 | C13: 8.3 | K13: Aprobat la inceputul anului | L13: Aprobat la sfirsitul anului | M13: Numarul mediu prevazut pe an | N13: Numarul mediu realizat la 01.01.2020 | O13: Real incadrat la începutul anului | P13: Real incadratla sfîrsitul perioadei
A14: funcții didactice, inclusiv | B14: 102 | C14: 8.4 | J14: cond. | K14: =D15+D19+D22 -> 0 | L14: =E15+E19+E22 -> 0 | M14: =F15+F19+F22 -> 0 | N14: =G15+G19+G22 -> 0 | O14: =H15+H19+H22 -> 0 | P14: =I15+I19+I22 -> 0
A15: de conducere | B15: 126 | C15: 8.5 | J15: exec | K15: =D16+D20+D23 -> 0 | L15: =E16+E20+E23 -> 0 | M15: =F16+F20+F23 -> 0 | N15: =G16+G20+G23 -> 0 | O15: =H16+H20+H23 -> 0 | P15: =I16+I20+I23 -> 0
A16: de execuție din care | B16: 145 | C16: 8.6 | J16: muncitori | K16: =D24 -> 0 | L16: =E24 -> 0 | M16: =F24 -> 0 | N16: =G24 -> 0 | O16: =H24 -> 0 | P16: =I24 -> 0
A17: cadre didactice de sprijin | B17: 146 | C17: 8.7 | J17: Total | K17: =K14+K15+K16 -> 0 | L17: =L14+L15+L16 -> 0 | M17: =M14+M15+M16 -> 0 | N17: =N14+N15+N16 -> 0 | O17: =O14+O15+O16 -> 0 | P17: =P14+P15+P16 -> 0
A18: funcții de specialitate, inclusiv | B18: 103 | C18: 8.8 | J18: control | K18: =D13-K17 -> 0 | L18: =E13-L17 -> 0 | M18: =F13-M17 -> 0 | N18: =G13-N17 -> 0 | O18: =H13-O17 -> 0 | P18: =I13-P17 -> 0
A19: de conducere | B19: 126 | C19: 8.9
A20: de execuție | B20: 145 | C20: 8.10
A21: funcții complexe, inclusiv | B21: 104 | C21: 8.11
A22: de conducere | B22: 126 | C22: 8.12
A23: de execuție | B23: 145 | C23: 8.13
A24: muncitori | B24: 177 | C24: 8.14
A25: Personal angajat în total, inclusiv | B25: 100 | C25: 8.15 | D25: =D26+D30+D33 -> 0 | E25: =E26+E30+E33 -> 0 | F25: x | G25: =G26+G30+G33 -> 0 | H25: =H26+H30+H33 -> 0 | I25: =I26+I30+I33 -> 0 | K25: Aprobat la inceputul anului | L25: Aprobat la sfirsitul anului | M25: Numarul mediu prevazut pe an | N25: Numarul mediu realizat la 01.01.2020 | O25: Real incadrat la începutul anului | P25: Real incadratla sfîrsitul perioadei
A26: funcții didactice, inclusiv | B26: 105 | C26: 8.16 | F26: x | J26: cond. | K26: =D27+D31+D34 -> 0 | L26: =E27+E31+E34 -> 0 | M26: =F27+F31+F34 -> #VALUE! | N26: =G27+G31+G34 -> 0 | O26: =H27+H31+H34 -> 0 | P26: =I27+I31+I34 -> 0
A27: de conducere | B27: 120 | C27: 8.17 | F27: x | J27: exec | K27: =D28+D32+D35 -> 0 | L27: =E28+E32+E35 -> 0 | M27: =F28+F32+F35 -> #VALUE! | N27: =G28+G32+G35 -> 0 | O27: =H28+H32+H35 -> 0 | P27: =I28+I32+I35 -> 0
A28: de execuție, din care | B28: 140 | C28: 8.18 | F28: x | J28: muncitori | K28: =D36 -> 0 | L28: =E36 -> 0 | M28: =F36 -> x | N28: =G36 -> 0 | O28: =H36 -> 0 | P28: =I36 -> 0
A29: cadre didactice de sprijin | B29: 147 | C29: 8.19 | F29: x | J29: Total | K29: =K26+K27+K28 -> 0 | L29: =L26+L27+L28 -> 0 | M29: =M26+M27+M28 -> #VALUE! | N29: =N26+N27+N28 -> 0 | O29: =O26+O27+O28 -> 0 | P29: =P26+P27+P28 -> 0
A30: funcții de specialitate, inclusiv | B30: 106 | C30: 8.20 | F30: x | J30: control | K30: =K29-D25 -> 0 | L30: =L29-E25 -> 0 | M30: =M29-F25 -> #VALUE! | N30: =N29-G25 -> 0 | O30: =O29-H25 -> 0 | P30: =P29-I25 -> 0
A31: de conducere | B31: 120 | C31: 8.21 | F31: x
A32: de execuție | B32: 140 | C32: 8.22 | F32: x
A33: funcții complexe, inclusiv | B33: 107 | C33: 8.23 | F33: x
A34: de conducere | B34: 120 | C34: 8.24 | F34: x
A35: de execuție | B35: 140 | C35: 8.25 | F35: x
A36: muncitori | B36: 175 | C36: 8.26 | F36: x
A37: Numărul personalului didactic beneficiar de compensații anuale, inclusiv | B37: 108 | C37: 8.27 | D37: =D38+D39 -> 15 | E37: =E38+E39 -> 15 | F37: x | G37: x | H37: =H38+H39 -> 15 | I37: =I38+I39 -> 15
A38: cu funcție de conducere | B38: 120 | C38: 8.28 | D38: 2 | E38: 2 | F38: x | G38: x | H38: =D38 -> 2 | I38: 2
A39: cu funcție de execuție | B39: 140 | C39: 8.29 | D39: 13 | E39: 13 | F39: x | G39: x | H39: =D39 -> 13 | I39: 13
A40: Retibuirea muncii în total, inclusiv | B40: 500 | C40: 8.30 | D40: x | E40: x | F40: =F41+F45+F48 -> 0 | G40: =G41+G45+G48 -> 0 | H40: x | I40: x
A41: funcții didactice, inclusiv | B41: 501 | C41: 8.31 | D41: x | E41: x | H41: x | I41: x
...

Sheet gim 9
H2: gim 9
A3: Aprobat prin ordinul Ministrului
A4: al Finanţelor al Republicii Moldova
A5: nr.___________al___________
A6: Retea, state si contingente ale instituriilor
A7: în perioada Tr.2 -2024 | J7: FD-048-BL
A8: Denumirea indicatorului | B8: codificatorul formularului | C8: Codul rindului | D8: Aprobat la inceputul anului | E8: Aprobat la sfirsitul anului | F8: Numarul mediu prevazut pe an | G8: Numarul mediu realizat la 30.09.2025 | H8: Real incadrat la începutul anului | I8: Real incadrat la sfîrsitul perioadei | J8: 09871 | K8: 0921 | L8: 8804 | M8: 00492 | N8: 0300
A9: 1 | B9: 2 | C9: 3 | D9: 4 | E9: 5 | F9: 6 | G9: 7 | H9: 8 | I9: 9
A10: RAPORT nr. 3-8 privind învățămîntul primar, gimnazial și liceal | C10: 8
A11: Instituții în total, inclusiv | B11: 1 | C11: 8.1 | F11: x | G11: x
A12: filiale | B12: 10 | C12: 8.2 | F12: x | G12: x
A13: Unități în state (posturi) în total, inclusiv | B13: 101 | C13: 8.3 | K13: Aprobat la inceputul anului | L13: Aprobat la sfirsitul anului | M13: Numarul mediu prevazut pe an | N13: Numarul mediu realizat la 01.01.2020 | O13: Real incadrat la începutul anului | P13: Real incadratla sfîrsitul perioadei
A14: funcții didactice, inclusiv | B14: 102 | C14: 8.4 | J14: cond. | K14: =D15+D19+D22 -> 0 | L14: =E15+E19+E22 -> 0 | M14: =F15+F19+F22 -> 0 | N14: =G15+G19+G22 -> 0 | O14: =H15+H19+H22 -> 0 | P14: =I15+I19+I22 -> 0
A15: de conducere | B15: 126 | C15: 8.5 | J15: exec | K15: =D16+D20+D23 -> 0 | L15: =E16+E20+E23 -> 0 | M15: =F16+F20+F23 -> 0 | N15: =G16+G20+G23 -> 0 | O15: =H16+H20+H23 -> 0 | P15: =I16+I20+I23 -> 0
A16: de execuție din care | B16: 145 | C16: 8.6 | J16: muncitori | K16: =D24 -> 0 | L16: =E24 -> 0 | M16: =F24 -> 0 | N16: =G24 -> 0 | O16: =H24 -> 0 | P16: =I24 -> 0
A17: cadre didactice de sprijin | B17: 146 | C17: 8.7 | J17: Total | K17: =K14+K15+K16 -> 0 | L17: =L14+L15+L16 -> 0 | M17: =M14+M15+M16 -> 0 | N17: =N14+N15+N16 -> 0 | O17: =O14+O15+O16 -> 0 | P17: =P14+P15+P16 -> 0
A18: funcții de specialitate, inclusiv | B18: 103 | C18: 8.8 | J18: control | K18: =D13-K17 -> 0 | L18: =E13-L17 -> 0 | M18: =F13-M17 -> 0 | N18: =G13-N17 -> 0 | O18: =H13-O17 -> 0 | P18: =I13-P17 -> 0
A19: de conducere | B19: 126 | C19: 8.9
A20: de execuție | B20: 145 | C20: 8.10
A21: funcții complexe, inclusiv | B21: 104 | C21: 8.11
A22: de conducere | B22: 126 | C22: 8.12
A23: de execuție | B23: 145 | C23: 8.13
A24: muncitori | B24: 177 | C24: 8.14
A25: Personal angajat în total, inclusiv | B25: 100 | C25: 8.15 | D25: =D26+D30+D33 -> 0 | E25: =E26+E30+E33 -> 0 | F25: x | G25: =G26+G30+G33 -> 0 | H25: =H26+H30+H33 -> 0 | I25: =I26+I30+I33 -> 0 | K25: Aprobat la inceputul anului | L25: Aprobat la sfirsitul anului | M25: Numarul mediu prevazut pe an | N25: Numarul mediu realizat la 01.01.2020 | O25: Real incadrat la începutul anului | P25: Real incadratla sfîrsitul perioadei
A26: funcții didactice, inclusiv | B26: 105 | C26: 8.16 | F26: x | J26: cond. | K26: =D27+D31+D34 -> 0 | L26: =E27+E31+E34 -> 0 | M26: =F27+F31+F34 -> #VALUE! | N26: =G27+G31+G34 -> 0 | O26: =H27+H31+H34 -> 0 | P26: =I27+I31+I34 -> 0
A27: de conducere | B27: 120 | C27: 8.17 | F27: x | J27: exec | K27: =D28+D32+D35 -> 0 | L27: =E28+E32+E35 -> 0 | M27: =F28+F32+F35 -> #VALUE! | N27: =G28+G32+G35 -> 0 | O27: =H28+H32+H35 -> 0 | P27: =I28+I32+I35 -> 0
A28: de execuție, din care | B28: 140 | C28: 8.18 | F28: x | J28: muncitori | K28: =D36 -> 0 | L28: =E36 -> 0 | M28: =F36 -> x | N28: =G36 -> 0 | O28: =H36 -> 0 | P28: =I36 -> 0
A29: cadre didactice de sprijin | B29: 147 | C29: 8.19 | F29: x | J29: Total | K29: =K26+K27+K28 -> 0 | L29: =L26+L27+L28 -> 0 | M29: =M26+M27+M28 -> #VALUE! | N29: =N26+N27+N28 -> 0 | O29: =O26+O27+O28 -> 0 | P29: =P26+P27+P28 -> 0
A30: funcții de specialitate, inclusiv | B30: 106 | C30: 8.20 | F30: x | J30: control | K30: =K29-D25 -> 0 | L30: =L29-E25 -> 0 | M30: =M29-F25 -> #VALUE! | N30: =N29-G25 -> 0 | O30: =O29-H25 -> 0 | P30: =P29-I25 -> 0
A31: de conducere | B31: 120 | C31: 8.21 | F31: x
A32: de execuție | B32: 140 | C32: 8.22 | F32: x
A33: funcții complexe, inclusiv | B33: 107 | C33: 8.23 | F33: x
A34: de conducere | B34: 120 | C34: 8.24 | F34: x
A35: de execuție | B35: 140 | C35: 8.25 | F35: x
A36: muncitori | B36: 175 | C36: 8.26 | F36: x
A37: Numărul personalului didactic beneficiar de compensații anuale, inclusiv | B37: 108 | C37: 8.27 | D37: =D38+D39 -> 16 | E37: =E38+E39 -> 17 | F37: x | G37: x | H37: =H38+H39 -> 16 | I37: =I38+I39 -> 17
A38: cu funcție de conducere | B38: 120 | C38: 8.28 | D38: 3 | E38: 3 | F38: x | G38: x | H38: =D38 -> 3 | I38: 3
A39: cu funcție de execuție | B39: 140 | C39: 8.29 | D39: 13 | E39: 14 | F39: x | G39: x | H39: =D39 -> 13 | I39: 14
A40: Retibuirea muncii în total, inclusiv | B40: 500 | C40: 8.30 | D40: x | E40: x | F40: =F41+F45+F48 -> 0 | G40: =G41+G45+G48 -> 0 | H40: x | I40: x
A41: funcții didactice, inclusiv | B41: 501 | C41: 8.31 | D41: x | E41: x | H41: x | I41: x
...

Sheet gim 14
H2: gim 14
A3: Aprobat prin ordinul Ministrului
A4: al Finanţelor al Republicii Moldova
A5: nr.___________al___________
A6: Retea, state si contingente ale instituriilor
A7: în perioada Tr.2 -2024 | J7: FD-048-BL
A8: Denumirea indicatorului | B8: codificatorul formularului | C8: Codul rindului | D8: Aprobat la inceputul anului | E8: Aprobat la sfirsitul anului | F8: Numarul mediu prevazut pe an | G8: Numarul mediu realizat la 30.09.2025 | H8: Real incadrat la începutul anului | I8: Real incadrat la sfîrsitul perioadei | J8: 09875 | K8: 0921 | L8: 8804 | M8: 00492 | N8: 0300
A9: 1 | B9: 2 | C9: 3 | D9: 4 | E9: 5 | F9: 6 | G9: 7 | H9: 8 | I9: 9
A10: RAPORT nr. 3-8 privind învățămîntul primar, gimnazial și liceal | C10: 8
A11: Instituții în total, inclusiv | B11: 1 | C11: 8.1 | F11: x | G11: x
A12: filiale | B12: 10 | C12: 8.2 | F12: x | G12: x
A13: Unități în state (posturi) în total, inclusiv | B13: 101 | C13: 8.3 | K13: Aprobat la inceputul anului | L13: Aprobat la sfirsitul anului | M13: Numarul mediu prevazut pe an | N13: Numarul mediu realizat la 01.01.2020 | O13: Real incadrat la începutul anului | P13: Real incadratla sfîrsitul perioadei
A14: funcții didactice, inclusiv | B14: 102 | C14: 8.4 | J14: cond. | K14: =D15+D19+D22 -> 0 | L14: =E15+E19+E22 -> 0 | M14: =F15+F19+F22 -> 0 | N14: =G15+G19+G22 -> 0 | O14: =H15+H19+H22 -> 0 | P14: =I15+I19+I22 -> 0
A15: de conducere | B15: 126 | C15: 8.5 | J15: exec | K15: =D16+D20+D23 -> 0 | L15: =E16+E20+E23 -> 0 | M15: =F16+F20+F23 -> 0 | N15: =G16+G20+G23 -> 0 | O15: =H16+H20+H23 -> 0 | P15: =I16+I20+I23 -> 0
A16: de execuție din care | B16: 145 | C16: 8.6 | J16: muncitori | K16: =D24 -> 0 | L16: =E24 -> 0 | M16: =F24 -> 0 | N16: =G24 -> 0 | O16: =H24 -> 0 | P16: =I24 -> 0
A17: cadre didactice de sprijin | B17: 146 | C17: 8.7 | J17: Total | K17: =K14+K15+K16 -> 0 | L17: =L14+L15+L16 -> 0 | M17: =M14+M15+M16 -> 0 | N17: =N14+N15+N16 -> 0 | O17: =O14+O15+O16 -> 0 | P17: =P14+P15+P16 -> 0
A18: funcții de specialitate, inclusiv | B18: 103 | C18: 8.8 | J18: control | K18: =D13-K17 -> 0 | L18: =E13-L17 -> 0 | M18: =F13-M17 -> 0 | N18: =G13-N17 -> 0 | O18: =H13-O17 -> 0 | P18: =I13-P17 -> 0
A19: de conducere | B19: 126 | C19: 8.9
A20: de execuție | B20: 145 | C20: 8.10
A21: funcții complexe, inclusiv | B21: 104 | C21: 8.11
A22: de conducere | B22: 126 | C22: 8.12
A23: de execuție | B23: 145 | C23: 8.13
A24: muncitori | B24: 177 | C24: 8.14
A25: Personal angajat în total, inclusiv | B25: 100 | C25: 8.15 | D25: =D26+D30+D33 -> 0 | E25: =E26+E30+E33 -> 0 | F25: x | G25: =G26+G30+G33 -> 0 | H25: =H26+H30+H33 -> 0 | I25: =I26+I30+I33 -> 0 | K25: Aprobat la inceputul anului | L25: Aprobat la sfirsitul anului | M25: Numarul mediu prevazut pe an | N25: Numarul mediu realizat la 01.01.2020 | O25: Real incadrat la începutul anului | P25: Real incadratla sfîrsitul perioadei
A26: funcții didactice, inclusiv | B26: 105 | C26: 8.16 | F26: x | J26: cond. | K26: =D27+D31+D34 -> 0 | L26: =E27+E31+E34 -> 0 | M26: =F27+F31+F34 -> #VALUE! | N26: =G27+G31+G34 -> 0 | O26: =H27+H31+H34 -> 0 | P26: =I27+I31+I34 -> 0
A27: de conducere | B27: 120 | C27: 8.17 | F27: x | J27: exec | K27: =D28+D32+D35 -> 0 | L27: =E28+E32+E35 -> 0 | M27: =F28+F32+F35 -> #VALUE! | N27: =G28+G32+G35 -> 0 | O27: =H28+H32+H35 -> 0 | P27: =I28+I32+I35 -> 0
A28: de execuție, din care | B28: 140 | C28: 8.18 | F28: x | J28: muncitori | K28: =D36 -> 0 | L28: =E36 -> 0 | M28: =F36 -> x | N28: =G36 -> 0 | O28: =H36 -> 0 | P28: =I36 -> 0
A29: cadre didactice de sprijin | B29: 147 | C29: 8.19 | F29: x | J29: Total | K29: =K26+K27+K28 -> 0 | L29: =L26+L27+L28 -> 0 | M29: =M26+M27+M28 -> #VALUE! | N29: =N26+N27+N28 -> 0 | O29: =O26+O27+O28 -> 0 | P29: =P26+P27+P28 -> 0
A30: funcții de specialitate, inclusiv | B30: 106 | C30: 8.20 | F30: x | J30: control | K30: =K29-D25 -> 0 | L30: =L29-E25 -> 0 | M30: =M29-F25 -> #VALUE! | N30: =N29-G25 -> 0 | O30: =O29-H25 -> 0 | P30: =P29-I25 -> 0
A31: de conducere | B31: 120 | C31: 8.21 | F31: x
A32: de execuție | B32: 140 | C32: 8.22 | F32: x
A33: funcții complexe, inclusiv | B33: 107 | C33: 8.23 | F33: x
A34: de conducere | B34: 120 | C34: 8.24 | F34: x
A35: de execuție | B35: 140 | C35: 8.25 | F35: x
A36: muncitori | B36: 175 | C36: 8.26 | F36: x
A37: Numărul personalului didactic beneficiar de compensații anuale, inclusiv | B37: 108 | C37: 8.27 | D37: =D38+D39 -> 20 | E37: =E38+E39 -> 21 | F37: x | G37: x | H37: =H38+H39 -> 20 | I37: =I38+I39 -> 21
A38: cu funcție de conducere | B38: 120 | C38: 8.28 | D38: 2 | E38: 2 | F38: x | G38: x | H38: =D38 -> 2 | I38: 2
A39: cu funcție de execuție | B39: 140 | C39: 8.29 | D39: 18 | E39: 19 | F39: x | G39: x | H39: =D39 -> 18 | I39: 19
A40: Retibuirea muncii în total, inclusiv | B40: 500 | C40: 8.30 | D40: x | E40: x | F40: =F41+F45+F48 -> 0 | G40: =G41+G45+G48 -> 0 | H40: x | I40: x
A41: funcții didactice, inclusiv | B41: 501 | C41: 8.31 | D41: x | E41: x | H41: x | I41: x
...

Sheet gim 19
H2: gim 19
A3: Aprobat prin ordinul Ministrului
A4: al Finanţelor al Republicii Moldova
A5: nr.___________al___________
A6: Retea, state si contingente ale instituriilor
A7: în perioada Tr.2 -2024 | J7: FD-048-BL
A8: Denumirea indicatorului | B8: codificatorul formularului | C8: Codul rindului | D8: Aprobat la inceputul anului | E8: Aprobat la sfirsitul anului | F8: Numarul mediu prevazut pe an | G8: Numarul mediu realizat la 30.09.2025 | H8: Real incadrat la începutul anului | I8: Real incadrat la sfîrsitul perioadei | J8: 14274 | K8: 0921 | L8: 8804 | M8: 00492 | N8: 0300
A9: 1 | B9: 2 | C9: 3 | D9: 4 | E9: 5 | F9: 6 | G9: 7 | H9: 8 | I9: 9
A10: RAPORT nr. 3-8 privind învățămîntul primar, gimnazial și liceal | C10: 8
A11: Instituții în total, inclusiv | B11: 1 | C11: 8.1 | F11: x | G11: x
A12: filiale | B12: 10 | C12: 8.2 | F12: x | G12: x
A13: Unități în state (posturi) în total, inclusiv | B13: 101 | C13: 8.3 | K13: Aprobat la inceputul anului | L13: Aprobat la sfirsitul anului | M13: Numarul mediu prevazut pe an | N13: Numarul mediu realizat la 01.01.2020 | O13: Real incadrat la începutul anului | P13: Real incadratla sfîrsitul perioadei
A14: funcții didactice, inclusiv | B14: 102 | C14: 8.4 | J14: cond. | K14: =D15+D19+D22 -> 0 | L14: =E15+E19+E22 -> 0 | M14: =F15+F19+F22 -> 0 | N14: =G15+G19+G22 -> 0 | O14: =H15+H19+H22 -> 0 | P14: =I15+I19+I22 -> 0
A15: de conducere | B15: 126 | C15: 8.5 | J15: exec | K15: =D16+D20+D23 -> 0 | L15: =E16+E20+E23 -> 0 | M15: =F16+F20+F23 -> 0 | N15: =G16+G20+G23 -> 0 | O15: =H16+H20+H23 -> 0 | P15: =I16+I20+I23 -> 0
A16: de execuție din care | B16: 145 | C16: 8.6 | J16: muncitori | K16: =D24 -> 0 | L16: =E24 -> 0 | M16: =F24 -> 0 | N16: =G24 -> 0 | O16: =H24 -> 0 | P16: =I24 -> 0
A17: cadre didactice de sprijin | B17: 146 | C17: 8.7 | J17: Total | K17: =K14+K15+K16 -> 0 | L17: =L14+L15+L16 -> 0 | M17: =M14+M15+M16 -> 0 | N17: =N14+N15+N16 -> 0 | O17: =O14+O15+O16 -> 0 | P17: =P14+P15+P16 -> 0
A18: funcții de specialitate, inclusiv | B18: 103 | C18: 8.8 | J18: control | K18: =D13-K17 -> 0 | L18: =E13-L17 -> 0 | M18: =F13-M17 -> 0 | N18: =G13-N17 -> 0 | O18: =H13-O17 -> 0 | P18: =I13-P17 -> 0
A19: de conducere | B19: 126 | C19: 8.9
A20: de execuție | B20: 145 | C20: 8.10
A21: funcții complexe, inclusiv | B21: 104 | C21: 8.11
A22: de conducere | B22: 126 | C22: 8.12
A23: de execuție | B23: 145 | C23: 8.13
A24: muncitori | B24: 177 | C24: 8.14
A25: Personal angajat în total, inclusiv | B25: 100 | C25: 8.15 | D25: =D26+D30+D33 -> 0 | E25: =E26+E30+E33 -> 0 | F25: x | G25: =G26+G30+G33 -> 0 | H25: =H26+H30+H33 -> 0 | I25: =I26+I30+I33 -> 0 | K25: Aprobat la inceputul anului | L25: Aprobat la sfirsitul anului | M25: Numarul mediu prevazut pe an | N25: Numarul mediu realizat la 01.01.2020 | O25: Real incadrat la începutul anului | P25: Real incadratla sfîrsitul perioadei
A26: funcții didactice, inclusiv | B26: 105 | C26: 8.16 | F26: x | J26: cond. | K26: =D27+D31+D34 -> 0 | L26: =E27+E31+E34 -> 0 | M26: =F27+F31+F34 -> #VALUE! | N26: =G27+G31+G34 -> 0 | O26: =H27+H31+H34 -> 0 | P26: =I27+I31+I34 -> 0
A27: de conducere | B27: 120 | C27: 8.17 | F27: x | J27: exec | K27: =D28+D32+D35 -> 0 | L27: =E28+E32+E35 -> 0 | M27: =F28+F32+F35 -> #VALUE! | N27: =G28+G32+G35 -> 0 | O27: =H28+H32+H35 -> 0 | P27: =I28+I32+I35 -> 0
A28: de execuție, din care | B28: 140 | C28: 8.18 | F28: x | J28: muncitori | K28: =D36 -> 0 | L28: =E36 -> 0 | M28: =F36 -> x | N28: =G36 -> 0 | O28: =H36 -> 0 | P28: =I36 -> 0
